Workbook

Sheet Plan de Cuentas
A1: Plan de Cuentas | F1: Nota: Esta importacion se debe realizar a través de Contabilidad >>> Plan de cuentas.
G2: Dato Obligatorio
G3: Dato Opcional
G4: Vacio
D6: 0 | E6: 1 | F6: 2 | G6: 3 | H6: 4 | I6: 5 | J6: 6 | K6: 7 | L6: 8 | M6: 9 | N6: 10 | O6: 11 | P6: 12 | Q6: 13 | R6: 14 | S6: 15 | T6: 16 | U6: 17 | V6: 18 | W6: 19 | X6: 20 | Y6: 21 | Z6: 22 | AA6: 23 | AB6: 24 | AC6: 25 | AD6: 26 | AE6: 27 | AF6: 28 | AG6: 29 | AH6: 30 | AI6: 31 | AJ6: 32 | AK6: 33 | AL6: 34 | AM6: 35
G7: 1 - 0 | H7: 1 - 0 | I7: D - H | J7: 1 - 0 | K7: 1 - 0 | L7: 1 - 0 | N7: 1 - 0 | O7: 1 - 0 | P7: 1 - 0 | Q7: 1 - 0 | R7: 1 - 0 | U7: Cuenta Contable | X7: 1 - 0 | Y7: 1 - 0 | Z7: 1 - 0 | AA7: 1 - 0 | AB7: 1 - 0 | AC7: 1 - 0 | AD7: 1 - 0 | AE7: 1 - 0 | AF7: 1 - 0 | AG7: 1 - 0
O10: Tipo de Apertura por Auxiliar | X10: Control de Imputabilidad | AI10: Habilitacion por Unidad de Negocios
D11: Cod de Cuenta | E11: Nombre | F11: Moneda | G11: Imputable | H11: Habilitada | I11: Saldo Habitual | J11: Resultado | K11: Monetaria | L11: Imputable por Parametros | M11: Auxiliar | N11: Hab. Elem por Auxiliar | O11: Cliente | P11: Proveedor | Q11: Empleado | R11: Alternativo | S11: Esq. De Distribucion | T11: Auxiliar Alternativo | U11: Cta Alternativa Ajuste x Inflacion | X11: Contabilidad | Y11: Ctas a Pagar Pagos | Z11: Ctas a Cobrar Recibos | AA11: Bancos | AB11: Ctas a Pagar Fact | AC11: Ctas a Cobrar Fact | AD11: Inventario | AE11: Activo Fijo | AF11: Punto de Vta | AG11: RRHH | AI11: Un de Negocios | AJ11: Un de Negocios | AK11: Un de Negocios | AL11: Un de Negocios | AM11: Un de Negocios
C12: Ejemplo | D12: 1.30.101 | E12: Activo Nuevo | F12: ARS | G12: 1 | H12: 1 | I12: D | J12: 1 | K12: 0 | L12: 0 | M12: CC | N12: 0 | O12: 0 | P12: 0 | Q12: 0 | R12: 0 | X12: 1 | Y12: 1 | Z12: 1 | AA12: 1 | AB12: 0 | AC12: 1 | AD12: 1 | AE12: 0 | AF12: 1 | AG12: 1 | AI12: 1
D13: =+Hoja1!A4 -> 1. | E13: =+Hoja1!B4 -> ACTIVO | F13: =+Hoja1!E4 -> PS | G13: =IF(Hoja1!F4="NO",0,1) -> 0 | H13: =IF(Hoja1!I4="NO",0,1) -> 1 | I13: D | J13: =IF(Hoja1!G4="NO",0,1) -> 0 | K13: =IF(Hoja1!H4="NO",0,1) -> 1 | L13: 0 | N13: 0 | O13: 0 | P13: 0 | Q13: 0 | R13: 0 | X13: =IF(G13=1,1,0) -> 0 | Y13: 0 | Z13: 0 | AA13: 0 | AB13: 0 | AC13: 0 | AD13: 0 | AE13: 0 | AF13: 0 | AG13: 0
D14: =+Hoja1!A5 -> 1.1. | E14: =+Hoja1!B5 -> ACTIVO CORRIENTE | F14: =+Hoja1!E5 -> PS | G14: =IF(Hoja1!F5="NO",0,1) -> 0 | H14: =IF(Hoja1!I5="NO",0,1) -> 1 | I14: D | J14: =IF(Hoja1!G5="NO",0,1) -> 0 | K14: =IF(Hoja1!H5="NO",0,1) -> 1 | L14: 0 | N14: 0 | O14: 0 | P14: 0 | Q14: 0 | R14: 0 | X14: =IF(G14=1,1,0) -> 0 | Y14: 0 | Z14: 0 | AA14: 0 | AB14: 0 | AC14: 0 | AD14: 0 | AE14: 0 | AF14: 0 | AG14: 0
D15: =+Hoja1!A6 -> 1101 | E15: =+Hoja1!B6 -> DISPONIBILIDADES | F15: =+Hoja1!E6 -> PS | G15: =IF(Hoja1!F6="NO",0,1) -> 0 | H15: =IF(Hoja1!I6="NO",0,1) -> 1 | I15: D | J15: =IF(Hoja1!G6="NO",0,1) -> 0 | K15: =IF(Hoja1!H6="NO",0,1) -> 1 | L15: 0 | N15: 0 | O15: 0 | P15: 0 | Q15: 0 | R15: 0 | X15: =IF(G15=1,1,0) -> 0 | Y15: 0 | Z15: 0 | AA15: 0 | AB15: 0 | AC15: 0 | AD15: 0 | AE15: 0 | AF15: 0 | AG15: 0
D16: =+Hoja1!A7 -> 110101 | E16: =+Hoja1!B7 -> CAJA | F16: =+Hoja1!E7 -> PS | G16: =IF(Hoja1!F7="NO",0,1) -> 1 | H16: =IF(Hoja1!I7="NO",0,1) -> 1 | I16: D | J16: =IF(Hoja1!G7="NO",0,1) -> 0 | K16: =IF(Hoja1!H7="NO",0,1) -> 1 | L16: 0 | N16: 0 | O16: 0 | P16: 0 | Q16: 0 | R16: 0 | X16: =IF(G16=1,1,0) -> 1 | Y16: 0 | Z16: 0 | AA16: 0 | AB16: 0 | AC16: 0 | AD16: 0 | AE16: 0 | AF16: 0 | AG16: 0
D17: =+Hoja1!A8 -> 110101001 | E17: =+Hoja1!B8 -> EFECTIVO - MONEDA NACIONAL | F17: =+Hoja1!E8 -> PS | G17: =IF(Hoja1!F8="NO",0,1) -> 1 | H17: =IF(Hoja1!I8="NO",0,1) -> 1 | I17: D | J17: =IF(Hoja1!G8="NO",0,1) -> 0 | K17: =IF(Hoja1!H8="NO",0,1) -> 1 | L17: 0 | N17: 0 | O17: 0 | P17: 0 | Q17: 0 | R17: 0 | X17: =IF(G17=1,1,0) -> 1 | Y17: 0 | Z17: 0 | AA17: 0 | AB17: 0 | AC17: 0 | AD17: 0 | AE17: 0 | AF17: 0 | AG17: 0
D18: =+Hoja1!A9 -> 110101002 | E18: =+Hoja1!B9 -> EFECTIVO - MONEDA EXTRANJERA | F18: =+Hoja1!E9 -> PS | G18: =IF(Hoja1!F9="NO",0,1) -> 1 | H18: =IF(Hoja1!I9="NO",0,1) -> 1 | I18: D | J18: =IF(Hoja1!G9="NO",0,1) -> 0 | K18: =IF(Hoja1!H9="NO",0,1) -> 1 | L18: 0 | N18: 0 | O18: 0 | P18: 0 | Q18: 0 | R18: 0 | X18: =IF(G18=1,1,0) -> 1 | Y18: 0 | Z18: 0 | AA18: 0 | AB18: 0 | AC18: 0 | AD18: 0 | AE18: 0 | AF18: 0 | AG18: 0
D19: =+Hoja1!A10 -> 110101010 | E19: =+Hoja1!B10 -> CAJA CHICA | F19: =+Hoja1!E10 -> PS | G19: =IF(Hoja1!F10="NO",0,1) -> 1 | H19: =IF(Hoja1!I10="NO",0,1) -> 1 | I19: D | J19: =IF(Hoja1!G10="NO",0,1) -> 0 | K19: =IF(Hoja1!H10="NO",0,1) -> 1 | L19: 0 | N19: 0 | O19: 0 | P19: 0 | Q19: 0 | R19: 0 | X19: =IF(G19=1,1,0) -> 1 | Y19: 0 | Z19: 0 | AA19: 0 | AB19: 0 | AC19: 0 | AD19: 0 | AE19: 0 | AF19: 0 | AG19: 0
D20: =+Hoja1!A11 -> 110105 | E20: =+Hoja1!B11 -> BANCOS | F20: =+Hoja1!E11 -> PS | G20: =IF(Hoja1!F11="NO",0,1) -> 0 | H20: =IF(Hoja1!I11="NO",0,1) -> 1 | I20: D | J20: =IF(Hoja1!G11="NO",0,1) -> 0 | K20: =IF(Hoja1!H11="NO",0,1) -> 1 | L20: 0 | N20: 0 | O20: 0 | P20: 0 | Q20: 0 | R20: 0 | X20: =IF(G20=1,1,0) -> 0 | Y20: 0 | Z20: 0 | AA20: 0 | AB20: 0 | AC20: 0 | AD20: 0 | AE20: 0 | AF20: 0 | AG20: 0
D21: =+Hoja1!A12 -> 110105110 | E21: =+Hoja1!B12 -> BANCO ARS | F21: =+Hoja1!E12 -> PS | G21: =IF(Hoja1!F12="NO",0,1) -> 1 | H21: =IF(Hoja1!I12="NO",0,1) -> 1 | I21: D | J21: =IF(Hoja1!G12="NO",0,1) -> 0 | K21: =IF(Hoja1!H12="NO",0,1) -> 1 | L21: 0 | N21: 0 | O21: 0 | P21: 0 | Q21: 0 | R21: 0 | X21: =IF(G21=1,1,0) -> 1 | Y21: 0 | Z21: 0 | AA21: 0 | AB21: 0 | AC21: 0 | AD21: 0 | AE21: 0 | AF21: 0 | AG21: 0
D22: =+Hoja1!A13 -> 110105111 | E22: =+Hoja1!B13 -> BANCO USD | F22: =+Hoja1!E13 -> DL | G22: =IF(Hoja1!F13="NO",0,1) -> 1 | H22: =IF(Hoja1!I13="NO",0,1) -> 1 | I22: D | J22: =IF(Hoja1!G13="NO",0,1) -> 0 | K22: =IF(Hoja1!H13="NO",0,1) -> 1 | L22: 0 | N22: 0 | O22: 0 | P22: 0 | Q22: 0 | R22: 0 | X22: =IF(G22=1,1,0) -> 1 | Y22: 0 | Z22: 0 | AA22: 0 | AB22: 0 | AC22: 0 | AD22: 0 | AE22: 0 | AF22: 0 | AG22: 0
D23: =+Hoja1!A14 -> 110105121 | E23: =+Hoja1!B14 -> REGULARIZADORA DE BANCOS | F23: =+Hoja1!E14 -> PS | G23: =IF(Hoja1!F14="NO",0,1) -> 1 | H23: =IF(Hoja1!I14="NO",0,1) -> 1 | I23: D | J23: =IF(Hoja1!G14="NO",0,1) -> 0 | K23: =IF(Hoja1!H14="NO",0,1) -> 1 | L23: 0 | N23: 0 | O23: 0 | P23: 0 | Q23: 0 | R23: 0 | X23: =IF(G23=1,1,0) -> 1 | Y23: 0 | Z23: 0 | AA23: 0 | AB23: 0 | AC23: 0 | AD23: 0 | AE23: 0 | AF23: 0 | AG23: 0
D24: =+Hoja1!A15 -> 110105148 | E24: =+Hoja1!B15 -> MERCADO PAGO | F24: =+Hoja1!E15 -> PS | G24: =IF(Hoja1!F15="NO",0,1) -> 1 | H24: =IF(Hoja1!I15="NO",0,1) -> 1 | I24: D | J24: =IF(Hoja1!G15="NO",0,1) -> 0 | K24: =IF(Hoja1!H15="NO",0,1) -> 1 | L24: 0 | N24: 0 | O24: 0 | P24: 0 | Q24: 0 | R24: 0 | X24: =IF(G24=1,1,0) -> 1 | Y24: 0 | Z24: 0 | AA24: 0 | AB24: 0 | AC24: 0 | AD24: 0 | AE24: 0 | AF24: 0 | AG24: 0
... D490: =+Hoja1!A481 -> 5501 | E490: =+Hoja1!B481 -> OTROS EGRESOS EXTRAORDINARIOS | F490: =+Hoja1!E481 -> PS | G490: =IF(Hoja1!F481="NO",0,1) -> 1 | H490: =IF(Hoja1!I481="NO",0,1) -> 1 | I490: D | J490: =IF(Hoja1!G481="NO",0,1) -> 1 | K490: =IF(Hoja1!H481="NO",0,1) -> 0 | L490: 0 | N490: 0 | O490: 0 | P490: 0 | Q490: 0 | R490: 0 | X490: =IF(G490=1,1,0) -> 1 | Y490: 0 | Z490: 0 | AA490: 0 | AB490: 0 | AC490: 0 | AD490: 0 | AE490: 0 | AF490: 0 | AG490: 0

Sheet Hoja1
A1: Empresa Modelo
A2: Plan de Cuentas
A3: Código | B3: Nombre | C3: Type 1 | D3: Type 2 | E3: Moneda | F3: Imp. | G3: Res. | H3: Mon. | I3: Hab. | L3: 1 | Q3: =CONCATENATE(L3,".") -> 1.
A4: 1. | B4: ACTIVO | C4: activ | D4: BS | E4: PS | F4: No | G4: No | H4: Si | I4: Si | L4: 1 | M4: 1
A5: 1.1. | B5: ACTIVO CORRIENTE | C5: activ | D5: BS | E5: PS | F5: No | G5: No | H5: Si | I5: Si | L5: 1 | M5: 1 | N5: 1
A6: 1101 | B6: DISPONIBILIDADES | C6: activ | D6: BS | E6: PS | F6: No | G6: No | H6: Si | I6: Si | L6: 1 | M6: 1 | N6: 1 | O6: 1
A7: 110101 | B7: CAJA | C7: activ | D7: BS | E7: PS | F7: Si | G7: No | H7: Si | I7: Si | L7: 1 | M7: 1 | N7: 1 | O7: 1 | P7: 1
A8: 110101001 | B8: EFECTIVO - MONEDA NACIONAL | C8: activ | D8: BS | E8: PS | F8: Si | G8: No | H8: Si | I8: Si | L8: 1 | M8: 1 | N8: 1 | O8: 1 | P8: 2
A9: 110101002 | B9: EFECTIVO - MONEDA EXTRANJERA | C9: activ | D9: BS | E9: PS | F9: Si | G9: No | H9: Si | I9: Si | L9: 1 | M9: 1 | N9: 1 | O9: 1 | P9: 10
A10: 110101010 | B10: CAJA CHICA | C10: activ | D10: BS | E10: PS | F10: Si | G10: No | H10: Si | I10: Si | L10: 1 | M10: 1 | N10: 1 | O10: 5
A11: 110105 | B11: BANCOS | C11: activ | D11: BS | E11: PS | F11: No | G11: No | H11: Si | I11: Si | L11: 1 | M11: 1 | N11: 1 | O11: 5 | P11: 110
A12: 110105110 | B12: BANCO ARS | C12: activ | D12: BS | E12: PS | F12: Si | G12: No | H12: Si | I12: Si | L12: 1 | M12: 1 | N12: 1 | O12: 5 | P12: 111
A13: 110105111 | B13: BANCO USD | C13: activ | D13: BS | E13: DL | F13: Si | G13: No | H13: Si | I13: Si | L13: 1 | M13: 1 | N13: 1 | O13: 5 | P13: 121
A14: 110105121 | B14: REGULARIZADORA DE BANCOS | C14: activ | D14: BS | E14: PS | F14: Si | G14: No | H14: Si | I14: Si | L14: 1 | M14: 1 | N14: 1 | O14: 5 | P14: 148
A15: 110105148 | B15: MERCADO PAGO | C15: activ | D15: BS | E15: PS | F15: Si | G15: No | H15: Si | I15: Si | L15: 1 | M15: 1 | N15: 2
A16: 1102 | B16: INVERSIONES | C16: activ | D16: BS | E16: PS | F16: No | G16: No | H16: Si | I16: Si | L16: 1 | M16: 1 | N16: 2 | O16: 1
A17: 110201 | B17: PLAZOS FIJOS | C17: activ | D17: BS | E17: PS | F17: No | G17: No | H17: Si | I17: Si | L17: 1 | M17: 1 | N17: 2 | O17: 1 | P17: 10
A18: 110201010 | B18: INVERSIONES | C18: activ | D18: BS | E18: PS | F18: Si | G18: No | H18: Si | I18: Si | L18: 1 | M18: 1 | N18: 2 | O18: 2
A19: 110202 | B19: BONOS | C19: activ | D19: BS | E19: PS | F19: No | G19: No | H19: Si | I19: Si | L19: 1 | M19: 1 | N19: 2 | O19: 2 | P19: 1
A20: 110202001 | B20: CUENTA COMITENTE | C20: activ | D20: BS | E20: PS | F20: Si | G20: No | H20: Si | I20: Si | L20: 1 | M20: 1 | N20: 2 | O20: 2 | P20: 9
A21: 110202009 | B21: ACCIONES | C21: activ | D21: BS | E21: PS | F21: Si | G21: No | H21: Si | I21: Si | L21: 1 | M21: 1 | N21: 2 | O21: 3 | P21: 10
A22: 110203010 | B22: TÍTULOS PUBLICOS USD | C22: activ | D22: BS | E22: DL | F22: Si | G22: No | H22: Si | I22: Si | L22: 1 | M22: 1 | N22: 2 | O22: 3 | P22: 12
A23: 110203012 | B23: FONDO COMÚN DE INVERSIONES ARS | C23: activ | D23: BS | E23: DL | F23: Si | G23: No | H23: Si | I23: Si | L23: 1 | M23: 1 | N23: 2 | O23: 3 | P23: 14
A24: 110203014 | B24: FONDO COMÚN DE INVERSIONES USD | C24: activ | D24: BS | E24: PS | F24: Si | G24: No | H24: Si | I24: Si | L24: 1 | M24: 1 | N24: 3
A25: 1103 | B25: CREDITOS POR VENTAS | C25: activ | D25: BS | E25: PS | F25: No | G25: No | H25: Si | I25: Si | L25: 1 | M25: 1 | N25: 3 | O25: 1
A26: 110301 | B26: CREDITOS POR VENTAS | C26: activ | D26: BS | E26: PS | F26: No | G26: No | H26: Si | I26: Si | L26: 1 | M26: 1 | N26: 3 | O26: 1 | P26: 1
A27: 110301001 | B27: DEUDORES POR VENTAS | C27: activ | D27: BS | E27: PS | F27: Si | G27: No | H27: Si | I27: Si | L27: 1 | M27: 1 | N27: 3 | O27: 1 | P27: 2
A28: 110301002 | B28: DEUDORES DEL EXTERIOR | C28: activ | D28: BS | E28: PS | F28: Si | G28: No | H28: Si | I28: Si | L28: 1 | M28: 1 | N28: 3 | O28: 1 | P28: 10
A29: 110301010 | B29: RECAUDADORA DE CLIENTE | C29: activ | D29: BS | E29: PS | F29: Si | G29: No | H29: Si | I29: Si | L29: 1 | M29: 1 | N29: 3 | O29: 1 | P29: 20
A30: 110301020 | B30: COBRANZAS PEND. MERC.EXT | C30: activ | D30: BS | E30: DL | F30: Si | G30: No | H30: Si | I30: Si | L30: 1 | M30: 1 | N30: 3 | O30: 1 | P30: 25
A31: 110301025 | B31: DOCUMENTOS A COBRAR | C31: activ | D31: BS | E31: PS | F31: Si | G31: No | H31: Si | I31: Si | L31: 1 | M31: 1 | N31: 3 | O31: 1 | P31: 30
A32: 110301030 | B32: DOCUMENTOS EN GESTION | C32: activ | D32: BS | E32: PS | F32: Si | G32: No | H32: Si | I32: Si | L32: 1 | M32: 1 | N32: 3 | O32: 1 | P32: 70
A33: 110301070 | B33: PREVISION PARA DS. INCOBR. | C33: activ | D33: BS | E33: PS | F33: Si | G33: No | H33: Si | I33: Si | L33: 1 | M33: 1 | N33: 3 | O33: 5
A34: 110305 | B34: VALORES A DEPOSITAR | C34: activ | D34: BS | E34: PS | F34: No | G34: No | H34: Si | I34: Si | L34: 1 | M34: 1 | N34: 3 | O34: 5 | P34: 1
A35: 110305001 | B35: VALORES PROPIOS DE CLIENTES | C35: activ | D35: BS | E35: PS | F35: Si | G35: No | H35: Si | I35: Si | L35: 1 | M35: 1 | N35: 3 | O35: 5 | P35: 10
A36: 110305010 | B36: VALORES DE TERCEROS | C36: activ | D36: BS | E36: PS | F36: Si | G36: No | H36: Si | I36: Si | L36: 1 | M36: 1 | N36: 3 | O36: 5 | P36: 20
A37: 110305020 | B37: VALORES ENTREGADOS EN CUSTODIA | C37: activ | D37: BS | E37: PS | F37: Si | G37: No | H37: Si | I37: Si | L37: 1 | M37: 1 | N37: 3 | O37: 5 | P37: 30
A38: 110305030 | B38: VALORES RECHAZADOS | C38: activ | D38: BS | E38: PS | F38: Si | G38: No | H38: Si | I38: Si | L38: 1 | M38: 1 | N38: 3 | O38: 5 | P38: 40
A39: 110305040 | B39: VALORES DE 3EROS. P/ GESTIONAR | C39: activ | D39: BS | E39: PS | F39: Si | G39: No | H39: Si | I39: Si | L39: 1 | M39: 1 | N39: 4
A40: 1104 | B40: OTROS CREDITOS | C40: activ | D40: BS | E40: PS | F40: No | G40: No | H40: Si | I40: Si | L40: 1 | M40: 1 | N40: 4 | O40: 1
...
