Workbook

Sheet Pegar Archivo Tienda Nube
A1: Planilla Web Tienda Nube
A6: 0 | B6: 1 | C6: 2 | D6: 3 | E6: 4 | F6: 5 | G6: 6 | H6: 7 | I6: 8 | J6: 9 | K6: 10 | L6: 11 | M6: 12 | N6: 13 | O6: 14 | P6: 15 | Q6: 16 | R6: 17 | S6: 18 | T6: 19 | U6: 20 | V6: 21 | W6: 22 | X6: 23 | Y6: 24 | Z6: 25 | AA6: 26 | AB6: 27 | AC6: 28 | AD6: 29 | AE6: 30 | AF6: 31 | AG6: 32 | AH6: 33 | AI6: 34 | AJ6: 35 | AK6: 36 | AL6: 37 | AM6: 38 | AN6: 39 | AO6: 40 | AP6: 41 | AQ6: 42 | AR6: 43 | AS6: 44 | AT6: 45
A7: Pegar debajo de esta fila | B7: Pegar debajo de esta fila | C7: Pegar debajo de esta fila | D7: Pegar debajo de esta fila | E7: Pegar debajo de esta fila | F7: Pegar debajo de esta fila | G7: Pegar debajo de esta fila | H7: Pegar debajo de esta fila | I7: Pegar debajo de esta fila | J7: Pegar debajo de esta fila | K7: Pegar debajo de esta fila | L7: Pegar debajo de esta fila | M7: Pegar debajo de esta fila | N7: Pegar debajo de esta fila | O7: Pegar debajo de esta fila | P7: Pegar debajo de esta fila | Q7: Pegar debajo de esta fila | R7: Pegar debajo de esta fila | S7: Pegar debajo de esta fila | T7: Pegar debajo de esta fila | U7: Pegar debajo de esta fila | V7: Pegar debajo de esta fila | W7: Pegar debajo de esta fila | X7: Pegar debajo de esta fila | Y7: Pegar debajo de esta fila | Z7: Pegar debajo de esta fila | AA7: Vacio | AB7: Pegar debajo de esta fila | AC7: Pegar debajo de esta fila | AD7: Pegar debajo de esta fila | AE7: Pegar debajo de esta fila | AF7: Pegar debajo de esta fila | AG7: Pegar debajo de esta fila | AH7: Pegar debajo de esta fila | AI7: Pegar debajo de esta fila | AJ7: Pegar debajo de esta fila | AK7: Pegar debajo de esta fila | AL7: Pegar debajo de esta fila | AM7: Pegar debajo de esta fila | AN7: Pegar debajo de esta fila | AO7: Pegar debajo de esta fila | AP7: Pegar debajo de esta fila | AQ7: Pegar debajo de esta fila | AR7: Pegar debajo de esta fila
A8: Número de orden | B8: Email | C8: Fecha | D8: Estado de la orden | E8: Estado del pago | F8: Estado del envío | G8: Moneda | H8: Subtotal de productos | I8: Descuento | J8: Costo de envío | K8: Total | L8: Nombre del comprador | M8: DNI / CUIT | N8: Teléfono | O8: Nombre para el envío | P8: Teléfono para el envío | Q8: Dirección | R8: Número | S8: Piso | T8: Localidad | U8: Ciudad | V8: Código postal | W8: Provincia o estado | X8: País | Y8: Medio de envío | Z8: Medio de pago | AB8: Cupón de descuento | AC8: Notas del comprador | AD8: Notas del vendedor | AE8: Fecha de pago | AF8: Fecha de envío | AG8: Nombre del producto | AH8: Precio del producto | AI8: Cantidad del producto | AJ8: SKU | AK8: Canal | AL8: Código de tracking del envío | AM8: Identificador de la transacción en el medio de pago | AN8: Identificador de la orden | AO8: Producto Físico | AP8: Persona que registró la venta | AQ8: Sucursal de venta | AR8: Vendedor
A9: 104 | B9: paulitaleal2208@hotmail.com | C9: 45764 | D9: Abierta | E9: Recibido | F9: Enviado | G9: ARS | H9: 35235 | I9: 0 | J9: 7675 | K9: 42910 | L9: Paula Leal | M9: 27285447947 | N9: 542302340750 | O9: Paula Leal | P9: 542302340750 | Q9: Maipu | R9: 55 | U9: Rancul | V9: 6214 | W9: La Pampa | X9: Argentina | Y9: Envío Nube - Correo Argentino Clásico a domicilio | Z9: Pago Nube | AE9: 45764 | AF9: 45764 | AG9: Cartera Coral (Negro) | AH9: 35235 | AI9: 1 | AJ9: N026 | AK9: Móvil | AL9: 1978190575CT42C301 | AM9: 01964418-4315-7eba-a4e1-df9bacfeb1ea | AN9: 1690758357 | AO9: Sí
A10: 105 | B10: mlorenagz@gmail.com | C10: 45765 | D10: Abierta | E10: Recibido | F10: Enviado | G10: ARS | H10: 40861 | I10: 8172.2 | J10: 6573 | K10: 39261.8 | L10: Lorena Gómez | M10: 32916618 | N10: 542216412873 | O10: Lorena Gómez | P10: 542216412873 | Q10: 531 Entre 20 Y 21 | R10: 2514 | U10: La Plata | V10: 1900 | W10: Buenos Aires | X10: Argentina | Y10: Envío Nube - Correo Argentino Clásico a domicilio | Z10: Pago Nube | AE10: 45765 | AF10: 45768 | AG10: Mochila Trébol | AH10: 40861 | AI10: 1 | AJ10: DA-005 | AK10: Móvil | AL10: 197814741C3I19A401 | AM10: 01964a1a-9dc4-7d31-8522-15d68996c86b | AN10: 1691449874 | AO10: Sí
A11: 106 | B11: viviana_ayrton@hotmail.com | C11: 45766 | D11: Abierta | E11: Recibido | F11: Enviado | G11: ARS | H11: 27470 | I11: 0 | J11: 6865.09 | K11: 34335.09 | L11: Viviana Zapata | M11: 23244790 | N11: 541157279299 | O11: Viviana zapata | P11: 541157279299 | Q11: Avenida Independencia | R11: 353 | S11: piso 11 | T11: san telmo | U11: Capital Federal | V11: 1099 | W11: Capital Federal | X11: Argentina | Y11: Correo Argentino Expreso - Envio a domicilio | Z11: Mercado Pago | AC11: lunes a viernes de 08 a 19 hs. | AE11: 45766 | AF11: 45772 | AG11: Bandolera Sol | AH11: 27470 | AI11: 1 | AJ11: AK-011# | AK11: Móvil | AL11: 00015482036AA5M001AC501 | AM11: 108452081109 | AN11: 1691907192 | AO11: Sí
A12: 109 | B12: adrinp64@gmail.com | C12: 45772 | D12: Abierta | E12: Recibido | F12: Entregado | G12: ARS | H12: 45325 | I12: 9065 | J12: 3169 | K12: 39429 | L12: Adriana Perez | M12: 16265200 | N12: 5493487537774 | O12: Adriana Perez | P12: 5493487537774 | Q12: RIVADAVIA | R12: 1161 | T12: Villa Mosconi | U12: Zarate | V12: 2800 | W12: Buenos Aires | X12: Argentina | Y12: Punto de retiro | Z12: Pago Nube | AE12: 45772 | AF12: 45776 | AG12: Bandolera Brisa (Negro) | AH12: 24723 | AI12: 1 | AJ12: 5561# | AK12: Móvil | AL12: 197810P19XG201C201 | AM12: 01966d3b-170d-7e0e-8bd3-88f3f42678e2 | AN12: 1695308421 | AO12: Sí
A13: 109 | B13: adrinp64@gmail.com | AG13: Riñonera Nube (Negro) | AH13: 20602 | AI13: 1 | AJ13: C25 | AO13: Sí
A14: 111 | B14: claudiaclaudiacastellano@gmail.com | C14: 45777 | D14: Abierta | E14: Recibido | F14: Entregado | G14: ARS | H14: 40861 | I14: 0 | J14: 5396 | K14: 46257 | L14: Claudia Castellano | M14: 29159746 | N14: 542284696070 | O14: Claudia Castellano | P14: 542284696070 | Q14: AV PRINGLES | R14: 2499 | T14: San Jacinto | U14: Olavarría | V14: 7400 | W14: Buenos Aires | X14: Argentina | Y14: Punto de retiro | Z14: Pago Nube | AE14: 45777 | AF14: 45784 | AG14: Mochila Trébol | AH14: 40861 | AI14: 1 | AJ14: DA-005 | AK14: Móvil | AL14: 1978173P124PEXA501 | AM14: 01968858-090f-781b-ab75-8c585dbf232d | AN14: 1698485688 | AO14: Sí
A15: 112 | B15: ursulandia@gmail.com | C15: 45783 | D15: Abierta | E15: Recibido | F15: Entregado | G15: ARS | H15: 40861 | I15: 8172.2 | J15: 5936 | K15: 38624.8 | L15: Jorge Alberto Serdarevich | M15: 27287682153 | N15: 541156039619 | O15: Jorge Alberto Serdarevich | P15: 541156039619 | Q15: Avenida Rivadavia | R15: 3049 | S15: 4° piso - departamento H | T15: Balvanera | U15: Capital Federal | V15: 1203 | W15: Capital Federal | X15: Argentina | Y15: Envío Nube - Correo Argentino Clásico a domicilio | Z15: Pago Nube | AE15: 45783 | AF15: 45786 | AG15: Mochila Trébol | AH15: 40861 | AI15: 1 | AJ15: DA-005 | AK15: Web | AL15: 197819AL9333CIC701 | AM15: 0196a78b-a9ec-7027-8d0a-c5f3dc6eeb85 | AN15: 1702356754 | AO15: Sí
A16: 113 | B16: nanucastro159@gmail.com | C16: 45785 | D16: Abierta | E16: Recibido | F16: Entregado | G16: ARS | H16: 40861 | I16: 0 | J16: 5936 | K16: 46797 | L16: Camila Naomi Castro | M16: 42410424 | N16: 541128483559 | O16: Camila Naomi Castro | P16: 541128483559 | Q16: Cerri, Daniel, Gral. | R16: 1589 | S16: Casa | T16: Buenos Aires | U16: Capital Federal | V16: 1291 | W16: Capital Federal | X16: Argentina | Y16: Envío Nube - Correo Argentino Clásico a domicilio | Z16: Pago Nube | AE16: 45785 | AF16: 45796 | AG16: Mochila Trébol | AH16: 40861 | AI16: 1 | AJ16: DA-005 | AK16: Móvil | AL16: 197810G2GAEA0X0501 | AM16: 0196b197-6674-7ad4-8ac1-f5687ad5070a | AN16: 1703697940 | AO16: Sí
A17: 114 | B17: thobbauj@gmail.com | C17: 45787 | D17: Abierta | E17: Recibido | F17: Entregado | G17: ARS | H17: 27470 | I17: 0 | J17: 5252 | K17: 32722 | L17: Sandra De Ambrosio | M17: 23291760 | N17: 541155846588 | O17: Sandra De Ambrosio | P17: 541155846588 | Q17: Corvalan | R17: 2302 | S17: 211 | T17: Haras Maria Eugenia R &amp; V | U17: Paso del Rey | V17: 1744 | W17: Gran Buenos Aires | X17: Argentina | Y17: Envío Nube - Correo Argentino Clásico a domicilio | Z17: Pago Nube | AE17: 45787 | AF17: 45790 | AG17: Bandolera Sol | AH17: 27470 | AI17: 1 | AJ17: AK-011# | AK17: Móvil | AL17: 197814AC9X11A9A301 | AM17: 0196bc4e-fe85-718a-b83e-2f3abc9a02a2 | AN17: 1705010827 | AO17: Sí
A18: 115 | B18: claudiamcoria@gmail.com | C18: 45790 | D18: Abierta | E18: Recibido | F18: Enviado | G18: ARS | H18: 40861 | I18: 0 | J18: 3371 | K18: 44232 | L18: Claudia Coria | M18: 25641917 | N18: 541161524087 | O18: Claudia Coria | P18: 541161524087 | Q18: LIBERTAD | R18: 602 | T18: Merlo | U18: Merlo | V18: 1722 | W18: Gran Buenos Aires | X18: Argentina | Y18: Punto de retiro | Z18: Pago Nube | AE18: 45790 | AF18: 45791 | AG18: Mochila Trébol | AH18: 40861 | AI18: 1 | AJ18: DA-005 | AK18: Web | AL18: 19781908G4A2AG1501 | AM18: 0196cbb7-eb52-7ade-b32e-05a306b73de0 | AN18: 1707704565 | AO18: Sí
A19: 116 | B19: celestevalltondre@gmail.com | C19: 45792 | D19: Abierta | E19: Recibido | F19: Entregado | G19: ARS | H19: 43740 | I19: 0 | J19: 3358 | K19: 47098 | L19: Celeste Valltondre | M19: 25115226 | N19: 541150179686 | O19: Celeste Valltondre | P19: 541150179686 | Q19: VERA | R19: 423 | T19: Caballito / Chacarita / Colegiales / Villa del Parque / Villa Real / Palermo / Recoleta / Villa Crespo | U19: Capital Federal | V19: 1414 | W19: Capital Federal | X19: Argentina | Y19: Punto de retiro | Z19: Pago Nube | AE19: 45792 | AF19: 45799 | AG19: Porta Celular Perla (Negro) | AH19: 19440 | AI19: 1 | AJ19: 83618 | AK19: Móvil | AL19: 197812PAA2CX5E1801 | AM19: 0196d6bc-de4f-7dc4-bc24-62cbca4e3934 | AN19: 1709609598 | AO19: Sí
A20: 116 | B20: celestevalltondre@gmail.com | AG20: Riñonera Siena (Negro) | AH20: 24300 | AI20: 1 | AJ20: ZT-020 | AO20: Sí
A21: 117 | B21: Ledezmajacqueline777@gmail.com | C21: 45793 | D21: Abierta | E21: Recibido | F21: Entregado | G21: ARS | H21: 61912 | I21: 0 | J21: 0 | K21: 61912 | L21: Jacqueline ledesma | M21: 46076602 | N21: 541138322608 | O21: Jacqueline ledesma | P21: 541138322608 | Q21: Av. Rodríguez Peña 1707 | R21: 1707 | T21: Santos lugares | U21: 3 De Febrero | V21: 1676 | W21: Gran Buenos Aires | X21: Argentina | Y21: Envío Nube - Correo Argentino Expreso a domicilio | Z21: Pago Nube | AC21: Envío a mí trabajo referencia: Restaurante Manus. | AE21: 45793 | AF21: 45799 | AG21: Mochila Cristal (Negro) | AH21: 41310 | AI21: 1 | AJ21: C5330 | AK21: Móvil | AL21: 197818G59351GGC501 | AM21: 0196d9d8-dede-7773-b679-1000fe65c40e | AN21: 1709934791 | AO21: Sí
A22: 117 | B22: Ledezmajacqueline777@gmail.com | AG22: Riñonera Nube (Negro) | AH22: 20602 | AI22: 1 | AJ22: C25 | AO22: Sí
A23: 118 | B23: flablanco@hotmail.com | C23: 45793 | D23: Abierta | E23: Recibido | F23: Entregado | G23: ARS | H23: 20602 | I23: 4120.4 | J23: 2963 | K23: 19444.6 | L23: Miriam Blanco | M23: 16762679 | N23: 5491134764144 | O23: Miriam Blanco | P23: 5491134764144 | Q23: GRAL JOSE G ARTIGAS | R23: 5067 | T23: Agronomía / Floresta / Monte Castro / Villa del Parque / Villa Santa Rita / Villa Real / Villa Pueyrredón / Villa Devoto | U23: Capital Federal | V23: 1419 | W23: Capital Federal | X23: Argentina | Y23: Punto de retiro | Z23: Pago Nube | AE23: 45796 | AF23: 45797 | AG23: Riñonera Nube (Negro) | AH23: 20602 | AI23: 1 | AJ23: C25 | AK23: Móvil | AL23: 197813A5T92A03C301 | AM23: 0196db39-8487-7879-b9f7-80c1696b2e0e | AN23: 1710193262 | AO23: Sí
A24: 119 | B24: bareillesclara@gmail.com | C24: 45796 | D24: Abierta | E24: Recibido | F24: Enviado | G24: ARS | H24: 65452 | I24: 13090.4 | J24: 0 | K24: 52361.6 | L24: Clara Bareilles | M24: 45153114 | N24: 541167171153 | O24: Clara Bareilles | P24: 541167171153 | Q24: AV CAMINO CENTENARIO | R24: 322 | T24: Juan Vucetich Ex Doctor R Levene | U24: La Plata | V24: 1894 | W24: Buenos Aires | X24: Argentina | Y24: Punto de retiro | Z24: Pago Nube | AE24: 45796 | AF24: 45797 | AG24: Bandolera Río | AH24: 30217 | AI24: 1 | AJ24: 1926# | AK24: Móvil | AL24: 197818A7ME45LMC501 | AM24: 0196e9d3-17f0-7fdc-abbf-54c7c551aeda | AN24: 1711963796 | AO24: Sí
A25: 119 | B25: bareillesclara@gmail.com | AG25: Cartera Coral (Negro) | AH25: 35235 | AI25: 1 | AJ25: N026 | AO25: Sí
A26: 120 | B26: mikafurrer.100@gmail.com | C26: 45799 | D26: Abierta | E26: Recibido | F26: No está empaquetado | G26: ARS | H26: 90544 | I26: 18108.8 | J26: 0 | K26: 72435.2 | L26: Micaela Furrer | M26: 40676633 | N26: 541134441515 | O26: Micaela Furrer | P26: 541134441515 | Q26: Junín | R26: 1461 | T26: Recoleta | U26: Capital Federal | V26: 1113 | W26: Capital Federal | X26: Argentina | Y26: Envío Nube - Correo Argentino Expreso a domicilio | Z26: Pago Nube | AE26: 45799 | AG26: Bolso Roca (Negro) | AH26: 48072 | AI26: 1 | AJ26: 3756 | AK26: Móvil | AL26: 197810PM6XAT0E1301 | AM26: 0196f7b7-44ec-72ec-a81b-53972a26c490 | AN26: 1711382551 | AO26: Sí
A27: 120 | B27: mikafurrer.100@gmail.com | AG27: Cartera Ámbar (Negro) | AH27: 21870 | AI27: 1 | AJ27: 83619 | AO27: Sí
A28: 120 | B28: mikafurrer.100@gmail.com | AG28: Riñonera Nube (Negro) | AH28: 20602 | AI28: 1 | AJ28: C25 | AO28: Sí
A29: 121 | B29: santiyanina10@gmail.com | C29: 45799 | D29: Abierta | E29: Recibido | F29: No está empaquetado | G29: ARS | H29: 61463 | I29: 12292.6 | J29: 0 | K29: 49170.4 | L29: Yanina Santi | M29: 42427113 | N29: 541139008728 | O29: Yanina Santi | P29: 541139008728 | Q29: Chile | R29: 1550 | S29: 3ro 13 | U29: Caba | V29: 1100 | W29: Capital Federal | X29: Argentina | Y29: Envío Nube - Correo Argentino Expreso a domicilio | Z29: Pago Nube | AE29: 45799 | AG29: Mochila Trébol | AH29: 40861 | AI29: 1 | AJ29: DA-005 | AK29: Móvil | AL29: 197818GGCMLTG01301 | AM29: 0196fb0f-7d8b-788c-b0c9-511e3b0e5367 | AN29: 1712349677 | AO29: Sí
A30: 121 | B30: santiyanina10@gmail.com | AG30: Riñonera Nube (Negro) | AH30: 20602 | AI30: 1 | AJ30: C25 | AO30: Sí
H31: Cobro

Sheet Comprobantes Masivos Global
A1: Comprobantes de Clientes (Tienda Nube) | F1: Según Tabla: | G1: Se debe ingresar en el sistema la parametrización previa, asi el sistema podrá leer las siglas correctamente.
G5: Configuraciones Previas
G6: Cliente 1: Crear un cliente General con código 1 que sea CF, o crear variable en Parámetros de Sistema >> Variables Generales
G7: PTN: Proceso Tienda Nueva en Proceso de Comprobantes Masivos con Modo de Utilizacion Pr Facturación Planilla de Cálculo
G8: Cat IVA: Dentro del PTN, determinar para RI,CF y MON el comprobante FBE (Factura B con remito y recibo simultaneo)
A9: Para ingresar la Importación se debe dirigir a Administración >> Cuentas a Cobrar >>> Operaciones >> Proceso de Comprobantes Masivos >> PTN. | G9: GF: Gastos de Flete en conceptos de ventas con modo de utilización Articulo Concepto
G10: DESM: Descuento masivo en conceptos de ventas con modo de utilización Artículo Descuento
G11: Vendedor 1: Crear un vendedor con código 1
G12: Cobrador: poner un cobrador por defecto en Parámetros de Cuentas a Cobrar >> Definiciones Generales >> Punto de Venta >> Cobrador
G13: Lista de Precios: Para que tome por default para todos los clientes, debe crear una lista de precios con código 0, en caso contrario ingresarla en el File Lista de Precios dentro del cliente
G14: Lista de Precios: debe tener el tilde Incluye Impuestos obligatoriamente, por lo que la Lista debe contener IVA
A17: 1 | B17: 2 | C17: 3 | D17: 4 | E17: 5 | F17: 6 | G17: 7 | H17: 8 | I17: 9 | J17: 10 | K17: 11 | L17: 12 | M17: 13 | N17: 14 | O17: 15 | P17: 16 | Q17: 17 | R17: 18 | S17: 19 | T17: 20 | U17: 21 | V17: 22 | W17: 23 | X17: 24 | Y17: 25 | Z17: 26 | AA17: 27 | AB17: 28 | AC17: 29 | AD17: 30 | AE17: 31 | AF17: 32 | AG17: 33 | AH17: 34 | AI17: 35 | AJ17: 36 | AK17: 37 | AL17: 38 | AM17: 39 | AN17: 40 | AO17: 41 | AP17: 42 | AQ17: 43 | AR17: 44 | AS17: 45
A18: Número Entero | B18: Texto (100) | C18: Tipo de Dato | D18: Texto (30) | E18: Texto (30) | F18: Texto (30) | G18: Texto (3) | H18: Formato Número | I18: Formato Número | J18: Formato Número | K18: Formato Número | L18: Texto (30) | M18: Texto (30) | N18: Texto (20) | O18: Texto (30) | P18: Texto (20) | Q18: Texto (10) | R18: Número Decimal | S18: Texto (10) | T18: Texto (10) | U18: Texto (20) | V18: Número Decimal | W18: Texto (20) | X18: Texto (20) | AE18: Tipo de Dato | AF18: Tipo de Dato | AH18: Número Decimal | AI18: Número Decimal
AH21: Filtrar esta columna sin los que tengan 0,00 si se desea subir todo junto
A22: Número de orden | B22: Email | C22: Fecha | D22: Estado de la orden | E22: Estado del pago | F22: Estado del envío | G22: Moneda | H22: Subtotal de productos | I22: Descuento | J22: Costo de envío | K22: Total | L22: Nombre del comprador | M22: DNI / CUIT | N22: Teléfono | O22: Nombre para el envío | P22: Teléfono para el envío | Q22: Dirección | R22: Número | S22: Piso | T22: Localidad | U22: Ciudad | V22: Código postal | W22: Provincia o estado | X22: País | Y22: Medio de envío | Z22: Medio de pago | AA22: Cupón de descuento | AC22: Notas del comprador | AD22: Notas del vendedor | AE22: Fecha de pago | AF22: Fecha de envío | AG22: Nombre del producto | AH22: Precio Art. | AI22: Cantidad | AJ22: Cod. Art. | AK22: Canal | AL22: Código de tracking del envío | AM22: Identificador de la transacción en el medio de pago | AN22: Identificador de la orden | AO22: Producto Físico | AP22: Persona que registró la venta | AQ22: Sucursal de venta | AR22: Vendedor | AS22: Cuenta Bancaria
A23: =+'Pegar Archivo Tienda Nube'!A9 -> 104 | B23: =+'Pegar Archivo Tienda Nube'!B9 -> paulitaleal2208@hotmail.com | C23: 45899 | D23: =+'Pegar Archivo Tienda Nube'!D9 -> Abierta | E23: =+'Pegar Archivo Tienda Nube'!E9 -> Recibido | F23: =+'Pegar Archivo Tienda Nube'!F9 -> Enviado | G23: =IF('Pegar Archivo Tienda Nube'!G9="ARS","PS","PS") -> PS | H23: =+'Pegar Archivo Tienda Nube'!H9 -> 35235 | I23: =+'Pegar Archivo Tienda Nube'!I9 -> 0 | J23: =+'Pegar Archivo Tienda Nube'!J9 -> 7675 | K23: =+'Pegar Archivo Tienda Nube'!K9 -> 42910 | L23: =+'Pegar Archivo Tienda Nube'!L9 -> Paula Leal | M23: =+'Pegar Archivo Tienda Nube'!M9 -> 27285447947 | N23: =+'Pegar Archivo Tienda Nube'!N9 -> 542302340750 | O23: =+'Pegar Archivo Tienda Nube'!O9 -> Paula Leal | ... Z23: =+'Pegar Archivo Tienda Nube'!Z9 -> Pago Nube | AA23: =+'Pegar Archivo Tienda Nube'!AB9 -> 0 | AC23: =+'Pegar Archivo Tienda Nube'!AC9 -> 0 | AD23: =+'Pegar Archivo Tienda Nube'!AD9 -> 0 | AE23: =+C23 -> 45899 | AF23: =+'Pegar Archivo Tienda Nube'!AF9 -> 45764 | AG23: =+'Pegar Archivo Tienda Nube'!AG9 -> Cartera Coral (Negro) | AH23: =+'Pegar Archivo Tienda Nube'!AH9 -> 35235 | AI23: =+'Pegar Archivo Tienda Nube'!AI9 -> 1 | AJ23: LZSBK12WH | AK23: =+'Pegar Archivo Tienda Nube'!AK9 -> Móvil | AL23: =+'Pegar Archivo Tienda Nube'!AL9 -> 1978190575CT42C301 | AM23: =+'Pegar Archivo Tienda Nube'!AM9 -> 01964418-4315-7eba-a4e1-df9bacfeb1ea | AN23: =+'Pegar Archivo Tienda Nube'!AN9 -> 1690758357 | AO23: =+'Pegar Archivo Tienda Nube'!AO9 -> Sí | AP23: =+'Pegar Archivo Tienda Nube'!AP9 -> 0 | AQ23: =+'Pegar Archivo Tienda Nube'!AQ9 -> 0 | AR23: =+'Pegar Archivo Tienda Nube'!AR9 -> 0 | AS23: 11
A24: =+'Pegar Archivo Tienda Nube'!A11 -> 106 | B24: =+'Pegar Archivo Tienda Nube'!B11 -> viviana_ayrton@hotmail.com | C24: 45899 | D24: =+'Pegar Archivo Tienda Nube'!D11 -> Abierta | E24: =+'Pegar Archivo Tienda Nube'!E11 -> Recibido | F24: =+'Pegar Archivo Tienda Nube'!F11 -> Enviado | G24: =IF('Pegar Archivo Tienda Nube'!G11="ARS","PS","PS") -> PS | H24: =+'Pegar Archivo Tienda Nube'!H11 -> 27470 | I24: =+'Pegar Archivo Tienda Nube'!I11 -> 0 | J24: =+'Pegar Archivo Tienda Nube'!J11 -> 6865.09 | K24: =+'Pegar Archivo Tienda Nube'!K11 -> 34335.09 | L24: =+'Pegar Archivo Tienda Nube'!L11 -> Viviana Zapata | M24: =+'Pegar Archivo Tienda Nube'!M11 -> 23244790 | N24: =+'Pegar Archivo Tienda Nube'!N11 -> 541157279299 | O24: =+'Pegar Archivo Tienda Nube'!O11 -> Viviana zapata | ... Z24: =+'Pegar Archivo Tienda Nube'!Z11 -> Mercado Pago | AA24: =+'Pegar Archivo Tienda Nube'!AB11 -> 0 | AC24: =+'Pegar Archivo Tienda Nube'!AC11 -> lunes a viernes de 08 a 19 hs. | AD24: =+'Pegar Archivo Tienda Nube'!AD11 -> 0 | AE24: =+C24 -> 45899 | AF24: =+'Pegar Archivo Tienda Nube'!AF11 -> 45772 | AG24: =+'Pegar Archivo Tienda Nube'!AG11 -> Bandolera Sol | AH24: =+'Pegar Archivo Tienda Nube'!AH11 -> 27470 | AI24: =+'Pegar Archivo Tienda Nube'!AI11 -> 1 | AJ24: LZSBK12WH | AK24: =+'Pegar Archivo Tienda Nube'!AK11 -> Móvil | AL24: =+'Pegar Archivo Tienda Nube'!AL11 -> 00015482036AA5M001AC501 | AM24: =+'Pegar Archivo Tienda Nube'!AM11 -> 108452081109 | AN24: =+'Pegar Archivo Tienda Nube'!AN11 -> 1691907192 | AO24: =+'Pegar Archivo Tienda Nube'!AO11 -> Sí | AP24: =+'Pegar Archivo Tienda Nube'!AP11 -> 0 | AQ24: =+'Pegar Archivo Tienda Nube'!AQ11 -> 0 | AR24: =+'Pegar Archivo Tienda Nube'!AR11 -> 0 | AS24: 11
A25: =+'Pegar Archivo Tienda Nube'!A12 -> 109 | B25: =+'Pegar Archivo Tienda Nube'!B12 -> adrinp64@gmail.com | C25: 45899 | D25: =+'Pegar Archivo Tienda Nube'!D12 -> Abierta | E25: =+'Pegar Archivo Tienda Nube'!E12 -> Recibido | F25: =+'Pegar Archivo Tienda Nube'!F12 -> Entregado | G25: =IF('Pegar Archivo Tienda Nube'!G12="ARS","PS","PS") -> PS | H25: =+'Pegar Archivo Tienda Nube'!H12 -> 45325 | I25: =+'Pegar Archivo Tienda Nube'!I12 -> 9065 | J25: =+'Pegar Archivo Tienda Nube'!J12 -> 3169 | K25: =+'Pegar Archivo Tienda Nube'!K12 -> 39429 | L25: =+'Pegar Archivo Tienda Nube'!L12 -> Adriana Perez | M25: =+'Pegar Archivo Tienda Nube'!M12 -> 16265200 | N25: =+'Pegar Archivo Tienda Nube'!N12 -> 5493487537774 | O25: =+'Pegar Archivo Tienda Nube'!O12 -> Adriana Perez | ... Z25: =+'Pegar Archivo Tienda Nube'!Z12 -> Pago Nube | AA25: =+'Pegar Archivo Tienda Nube'!AB12 -> 0 | AC25: =+'Pegar Archivo Tienda Nube'!AC12 -> 0 | AD25: =+'Pegar Archivo Tienda Nube'!AD12 -> 0 | AE25: =+C25 -> 45899 | AF25: =+'Pegar Archivo Tienda Nube'!AF12 -> 45776 | AG25: =+'Pegar Archivo Tienda Nube'!AG12 -> Bandolera Brisa (Negro) | AH25: =+'Pegar Archivo Tienda Nube'!AH12 -> 24723 | AI25: =+'Pegar Archivo Tienda Nube'!AI12 -> 1 | AJ25: LZSBK12WH | AK25: =+'Pegar Archivo Tienda Nube'!AK12 -> Móvil | AL25: =+'Pegar Archivo Tienda Nube'!AL12 -> 197810P19XG201C201 | AM25: =+'Pegar Archivo Tienda Nube'!AM12 -> 01966d3b-170d-7e0e-8bd3-88f3f42678e2 | AN25: =+'Pegar Archivo Tienda Nube'!AN12 -> 1695308421 | AO25: =+'Pegar Archivo Tienda Nube'!AO12 -> Sí | AP25: =+'Pegar Archivo Tienda Nube'!AP12 -> 0 | AQ25: =+'Pegar Archivo Tienda Nube'!AQ12 -> 0 | AR25: =+'Pegar Archivo Tienda Nube'!AR12 -> 0 | AS25: 11
A26: =+'Pegar Archivo Tienda Nube'!A13 -> 109 | B26: =+'Pegar Archivo Tienda Nube'!B13 -> adrinp64@gmail.com | C26: 45892 | D26: =+'Pegar Archivo Tienda Nube'!D13 -> 0 | E26: =+'Pegar Archivo Tienda Nube'!E13 -> 0 | F26: =+'Pegar Archivo Tienda Nube'!F13 -> 0 | G26: =IF('Pegar Archivo Tienda Nube'!G13="ARS","PS","PS") -> PS | H26: =+'Pegar Archivo Tienda Nube'!H13 -> 0 | I26: =+'Pegar Archivo Tienda Nube'!I13 -> 0 | J26: =+'Pegar Archivo Tienda Nube'!J13 -> 0 | K26: =+'Pegar Archivo Tienda Nube'!K13 -> 0 | L26: =+'Pegar Archivo Tienda Nube'!L13 -> 0 | M26: =+'Pegar Archivo Tienda Nube'!M13 -> 0 | N26: =+'Pegar Archivo Tienda Nube'!N13 -> 0 | O26: =+'Pegar Archivo Tienda Nube'!O13 -> 0 | ... Z26: =+'Pegar Archivo Tienda Nube'!Z13 -> 0 | AA26: =+'Pegar Archivo Tienda Nube'!AB13 -> 0 | AC26: =+'Pegar Archivo Tienda Nube'!AC13 -> 0 | AD26: =+'Pegar Archivo Tienda Nube'!AD13 -> 0 | AE26: =+C26 -> 45892 | AF26: =+'Pegar Archivo Tienda Nube'!AF13 -> 0 | AG26: =+'Pegar Archivo Tienda Nube'!AG13 -> Riñonera Nube (Negro) | AH26: =+'Pegar Archivo Tienda Nube'!AH13 -> 20602 | AI26: =+'Pegar Archivo Tienda Nube'!AI13 -> 1 | AJ26: LZSBK12WH | AK26: =+'Pegar Archivo Tienda Nube'!AK13 -> 0 | AL26: =+'Pegar Archivo Tienda Nube'!AL13 -> 0 | AM26: =+'Pegar Archivo Tienda Nube'!AM13 -> 0 | AN26: =+'Pegar Archivo Tienda Nube'!AN13 -> 0 | AO26: =+'Pegar Archivo Tienda Nube'!AO13 -> Sí | AP26: =+'Pegar Archivo Tienda Nube'!AP13 -> 0 | AQ26: =+'Pegar Archivo Tienda Nube'!AQ13 -> 0 | AR26: =+'Pegar Archivo Tienda Nube'!AR13 -> 0 | AS26: 11
A27: =+'Pegar Archivo Tienda Nube'!A14 -> 111 | B27: =+'Pegar Archivo Tienda Nube'!B14 -> claudiaclaudiacastellano@gmail.com | C27: 45899 | D27: =+'Pegar Archivo Tienda Nube'!D14 -> Abierta | E27: =+'Pegar Archivo Tienda Nube'!E14 -> Recibido | F27: =+'Pegar Archivo Tienda Nube'!F14 -> Entregado | G27: =IF('Pegar Archivo Tienda Nube'!G14="ARS","PS","PS") -> PS | H27: =+'Pegar Archivo Tienda Nube'!H14 -> 40861 | I27: =+'Pegar Archivo Tienda Nube'!I14 -> 0 | J27: =+'Pegar Archivo Tienda Nube'!J14 -> 5396 | K27: =+'Pegar Archivo Tienda Nube'!K14 -> 46257 | L27: =+'Pegar Archivo Tienda Nube'!L14 -> Claudia Castellano | M27: =+'Pegar Archivo Tienda Nube'!M14 -> 29159746 | N27: =+'Pegar Archivo Tienda Nube'!N14 -> 542284696070 | O27: =+'Pegar Archivo Tienda Nube'!O14 -> Claudia Castellano | ... Z27: =+'Pegar Archivo Tienda Nube'!Z14 -> Pago Nube | AA27: =+'Pegar Archivo Tienda Nube'!AB14 -> 0 | AC27: =+'Pegar Archivo Tienda Nube'!AC14 -> 0 | AD27: =+'Pegar Archivo Tienda Nube'!AD14 -> 0 | AE27: =+C27 -> 45899 | AF27: =+'Pegar Archivo Tienda Nube'!AF14 -> 45784 | AG27: =+'Pegar Archivo Tienda Nube'!AG14 -> Mochila Trébol | AH27: =+'Pegar Archivo Tienda Nube'!AH14 -> 40861 | AI27: =+'Pegar Archivo Tienda Nube'!AI14 -> 1 | AJ27: LZSBK12WH | AK27: =+'Pegar Archivo Tienda Nube'!AK14 -> Móvil | AL27: =+'Pegar Archivo Tienda Nube'!AL14 -> 1978173P124PEXA501 | AM27: =+'Pegar Archivo Tienda Nube'!AM14 -> 01968858-090f-781b-ab75-8c585dbf232d | AN27: =+'Pegar Archivo Tienda Nube'!AN14 -> 1698485688 | AO27: =+'Pegar Archivo Tienda Nube'!AO14 -> Sí | AP27: =+'Pegar Archivo Tienda Nube'!AP14 -> 0 | AQ27: =+'Pegar Archivo Tienda Nube'!AQ14 -> 0 | AR27: =+'Pegar Archivo Tienda Nube'!AR14 -> 0 | AS27: 11
A28: =+'Pegar Archivo Tienda Nube'!A15 -> 112 | B28: =+'Pegar Archivo Tienda Nube'!B15 -> ursulandia@gmail.com | C28: 45899 | D28: =+'Pegar Archivo Tienda Nube'!D15 -> Abierta | E28: =+'Pegar Archivo Tienda Nube'!E15 -> Recibido | F28: =+'Pegar Archivo Tienda Nube'!F15 -> Entregado | G28: =IF('Pegar Archivo Tienda Nube'!G15="ARS","PS","PS") -> PS | H28: =+'Pegar Archivo Tienda Nube'!H15 -> 40861 | I28: =+'Pegar Archivo Tienda Nube'!I15 -> 8172.2 | J28: =+'Pegar Archivo Tienda Nube'!J15 -> 5936 | K28: =+'Pegar Archivo Tienda Nube'!K15 -> 38624.8 | L28: =+'Pegar Archivo Tienda Nube'!L15 -> Jorge Alberto Serdarevich | M28: =+'Pegar Archivo Tienda Nube'!M15 -> 27287682153 | N28: =+'Pegar Archivo Tienda Nube'!N15 -> 541156039619 | O28: =+'Pegar Archivo Tienda Nube'!O15 -> Jorge Alberto Serdarevich | ... Z28: =+'Pegar Archivo Tienda Nube'!Z15 -> Pago Nube | AA28: =+'Pegar Archivo Tienda Nube'!AB15 -> 0 | AC28: =+'Pegar Archivo Tienda Nube'!AC15 -> 0 | AD28: =+'Pegar Archivo Tienda Nube'!AD15 -> 0 | AE28: =+C28 -> 45899 | AF28: =+'Pegar Archivo Tienda Nube'!AF15 -> 45786 | AG28: =+'Pegar Archivo Tienda Nube'!AG15 -> Mochila Trébol | AH28: =+'Pegar Archivo Tienda Nube'!AH15 -> 40861 | AI28: =+'Pegar Archivo Tienda Nube'!AI15 -> 1 | AJ28: LZSBK12WH | AK28: =+'Pegar Archivo Tienda Nube'!AK15 -> Web | AL28: =+'Pegar Archivo Tienda Nube'!AL15 -> 197819AL9333CIC701 | AM28: =+'Pegar Archivo Tienda Nube'!AM15 -> 0196a78b-a9ec-7027-8d0a-c5f3dc6eeb85 | AN28: =+'Pegar Archivo Tienda Nube'!AN15 -> 1702356754 | AO28: =+'Pegar Archivo Tienda Nube'!AO15 -> Sí | AP28: =+'Pegar Archivo Tienda Nube'!AP15 -> 0 | AQ28: =+'Pegar Archivo Tienda Nube'!AQ15 -> 0 | AR28: =+'Pegar Archivo Tienda Nube'!AR15 -> 0 | AS28: 11
A29: =+'Pegar Archivo Tienda Nube'!A16 -> 113 | B29: =+'Pegar Archivo Tienda Nube'!B16 -> nanucastro159@gmail.com | C29: 45899 | D29: =+'Pegar Archivo Tienda Nube'!D16 -> Abierta | E29: =+'Pegar Archivo Tienda Nube'!E16 -> Recibido | F29: =+'Pegar Archivo Tienda Nube'!F16 -> Entregado | G29: =IF('Pegar Archivo Tienda Nube'!G16="ARS","PS","PS") -> PS | H29: =+'Pegar Archivo Tienda Nube'!H16 -> 40861 | I29: =+'Pegar Archivo Tienda Nube'!I16 -> 0 | J29: =+'Pegar Archivo Tienda Nube'!J16 -> 5936 | K29: =+'Pegar Archivo Tienda Nube'!K16 -> 46797 | L29: =+'Pegar Archivo Tienda Nube'!L16 -> Camila Naomi Castro | M29: =+'Pegar Archivo Tienda Nube'!M16 -> 42410424 | N29: =+'Pegar Archivo Tienda Nube'!N16 -> 541128483559 | O29: =+'Pegar Archivo Tienda Nube'!O16 -> Camila Naomi Castro | ... Z29: =+'Pegar Archivo Tienda Nube'!Z16 -> Pago Nube | AA29: =+'Pegar Archivo Tienda Nube'!AB16 -> 0 | AC29: =+'Pegar Archivo Tienda Nube'!AC16 -> 0 | AD29: =+'Pegar Archivo Tienda Nube'!AD16 -> 0 | AE29: =+C29 -> 45899 | AF29: =+'Pegar Archivo Tienda Nube'!AF16 -> 45796 | AG29: =+'Pegar Archivo Tienda Nube'!AG16 -> Mochila Trébol | AH29: =+'Pegar Archivo Tienda Nube'!AH16 -> 40861 | AI29: =+'Pegar Archivo Tienda Nube'!AI16 -> 1 | AJ29: LZSBK12WH | AK29: =+'Pegar Archivo Tienda Nube'!AK16 -> Móvil | AL29: =+'Pegar Archivo Tienda Nube'!AL16 -> 197810G2GAEA0X0501 | AM29: =+'Pegar Archivo Tienda Nube'!AM16 -> 0196b197-6674-7ad4-8ac1-f5687ad5070a | AN29: =+'Pegar Archivo Tienda Nube'!AN16 -> 1703697940 | AO29: =+'Pegar Archivo Tienda Nube'!AO16 -> Sí | AP29: =+'Pegar Archivo Tienda Nube'!AP16 -> 0 | AQ29: =+'Pegar Archivo Tienda Nube'!AQ16 -> 0 | AR29: =+'Pegar Archivo Tienda Nube'!AR16 -> 0 | AS29: 11
A30: =+'Pegar Archivo Tienda Nube'!A17 -> 114 | B30: =+'Pegar Archivo Tienda Nube'!B17 -> thobbauj@gmail.com | C30: 45899 | D30: =+'Pegar Archivo Tienda Nube'!D17 -> Abierta | E30: =+'Pegar Archivo Tienda Nube'!E17 -> Recibido | F30: =+'Pegar Archivo Tienda Nube'!F17 -> Entregado | G30: =IF('Pegar Archivo Tienda Nube'!G17="ARS","PS","PS") -> PS | H30: =+'Pegar Archivo Tienda Nube'!H17 -> 27470 | I30: =+'Pegar Archivo Tienda Nube'!I17 -> 0 | J30: =+'Pegar Archivo Tienda Nube'!J17 -> 5252 | K30: =+'Pegar Archivo Tienda Nube'!K17 -> 32722 | L30: =+'Pegar Archivo Tienda Nube'!L17 -> Sandra De Ambrosio | M30: =+'Pegar Archivo Tienda Nube'!M17 -> 23291760 | N30: =+'Pegar Archivo Tienda Nube'!N17 -> 541155846588 | O30: =+'Pegar Archivo Tienda Nube'!O17 -> Sandra De Ambrosio | ... Z30: =+'Pegar Archivo Tienda Nube'!Z17 -> Pago Nube | AA30: =+'Pegar Archivo Tienda Nube'!AB17 -> 0 | AC30: =+'Pegar Archivo Tienda Nube'!AC17 -> 0 | AD30: =+'Pegar Archivo Tienda Nube'!AD17 -> 0 | AE30: =+C30 -> 45899 | AF30: =+'Pegar Archivo Tienda Nube'!AF17 -> 45790 | AG30: =+'Pegar Archivo Tienda Nube'!AG17 -> Bandolera Sol | AH30: =+'Pegar Archivo Tienda Nube'!AH17 -> 27470 | AI30: =+'Pegar Archivo Tienda Nube'!AI17 -> 1 | AJ30: LZSBK12WH | AK30: =+'Pegar Archivo Tienda Nube'!AK17 -> Móvil | AL30: =+'Pegar Archivo Tienda Nube'!AL17 -> 197814AC9X11A9A301 | AM30: =+'Pegar Archivo Tienda Nube'!AM17 -> 0196bc4e-fe85-718a-b83e-2f3abc9a02a2 | AN30: =+'Pegar Archivo Tienda Nube'!AN17 -> 1705010827 | AO30: =+'Pegar Archivo Tienda Nube'!AO17 -> Sí | AP30: =+'Pegar Archivo Tienda Nube'!AP17 -> 0 | AQ30: =+'Pegar Archivo Tienda Nube'!AQ17 -> 0 | AR30: =+'Pegar Archivo Tienda Nube'!AR17 -> 0 | AS30: 11
A31: =+'Pegar Archivo Tienda Nube'!A18 -> 115 | B31: =+'Pegar Archivo Tienda Nube'!B18 -> claudiamcoria@gmail.com | C31: 45899 | D31: =+'Pegar Archivo Tienda Nube'!D18 -> Abierta | E31: =+'Pegar Archivo Tienda Nube'!E18 -> Recibido | F31: =+'Pegar Archivo Tienda Nube'!F18 -> Enviado | G31: =IF('Pegar Archivo Tienda Nube'!G18="ARS","PS","PS") -> PS | H31: =+'Pegar Archivo Tienda Nube'!H18 -> 40861 | I31: =+'Pegar Archivo Tienda Nube'!I18 -> 0 | J31: =+'Pegar Archivo Tienda Nube'!J18 -> 3371 | K31: =+'Pegar Archivo Tienda Nube'!K18 -> 44232 | L31: =+'Pegar Archivo Tienda Nube'!L18 -> Claudia Coria | M31: =+'Pegar Archivo Tienda Nube'!M18 -> 25641917 | N31: =+'Pegar Archivo Tienda Nube'!N18 -> 541161524087 | O31: =+'Pegar Archivo Tienda Nube'!O18 -> Claudia Coria | ... Z31: =+'Pegar Archivo Tienda Nube'!Z18 -> Pago Nube | AA31: =+'Pegar Archivo Tienda Nube'!AB18 -> 0 | AC31: =+'Pegar Archivo Tienda Nube'!AC18 -> 0 | AD31: =+'Pegar Archivo Tienda Nube'!AD18 -> 0 | AE31: =+C31 -> 45899 | AF31: =+'Pegar Archivo Tienda Nube'!AF18 -> 45791 | AG31: =+'Pegar Archivo Tienda Nube'!AG18 -> Mochila Trébol | AH31: =+'Pegar Archivo Tienda Nube'!AH18 -> 40861 | AI31: =+'Pegar Archivo Tienda Nube'!AI18 -> 1 | AJ31: LZSBK12WH | AK31: =+'Pegar Archivo Tienda Nube'!AK18 -> Web | AL31: =+'Pegar Archivo Tienda Nube'!AL18 -> 19781908G4A2AG1501 | AM31: =+'Pegar Archivo Tienda Nube'!AM18 -> 0196cbb7-eb52-7ade-b32e-05a306b73de0 | AN31: =+'Pegar Archivo Tienda Nube'!AN18 -> 1707704565 | AO31: =+'Pegar Archivo Tienda Nube'!AO18 -> Sí | AP31: =+'Pegar Archivo Tienda Nube'!AP18 -> 0 | AQ31: =+'Pegar Archivo Tienda Nube'!AQ18 -> 0 | AR31: =+'Pegar Archivo Tienda Nube'!AR18 -> 0 | AS31: 11
A32: =+'Pegar Archivo Tienda Nube'!A19 -> 116 | B32: =+'Pegar Archivo Tienda Nube'!B19 -> celestevalltondre@gmail.com | C32: 45899 | D32: =+'Pegar Archivo Tienda Nube'!D19 -> Abierta | E32: =+'Pegar Archivo Tienda Nube'!E19 -> Recibido | F32: =+'Pegar Archivo Tienda Nube'!F19 -> Entregado | G32: =IF('Pegar Archivo Tienda Nube'!G19="ARS","PS","PS") -> PS | H32: =+'Pegar Archivo Tienda Nube'!H19 -> 43740 | I32: =+'Pegar Archivo Tienda Nube'!I19 -> 0 | J32: =+'Pegar Archivo Tienda Nube'!J19 -> 3358 | K32: =+'Pegar Archivo Tienda Nube'!K19 -> 47098 | L32: =+'Pegar Archivo Tienda Nube'!L19 -> Celeste Valltondre | M32: =+'Pegar Archivo Tienda Nube'!M19 -> 25115226 | N32: =+'Pegar Archivo Tienda Nube'!N19 -> 541150179686 | O32: =+'Pegar Archivo Tienda Nube'!O19 -> Celeste Valltondre | ... Z32: =+'Pegar Archivo Tienda Nube'!Z19 -> Pago Nube | AA32: =+'Pegar Archivo Tienda Nube'!AB19 -> 0 | AC32: =+'Pegar Archivo Tienda Nube'!AC19 -> 0 | AD32: =+'Pegar Archivo Tienda Nube'!AD19 -> 0 | AE32: =+C32 -> 45899 | AF32: =+'Pegar Archivo Tienda Nube'!AF19 -> 45799 | AG32: =+'Pegar Archivo Tienda Nube'!AG19 -> Porta Celular Perla (Negro) | AH32: =+'Pegar Archivo Tienda Nube'!AH19 -> 19440 | AI32: =+'Pegar Archivo Tienda Nube'!AI19 -> 1 | AJ32: LZSBK12WH | AK32: =+'Pegar Archivo Tienda Nube'!AK19 -> Móvil | AL32: =+'Pegar Archivo Tienda Nube'!AL19 -> 197812PAA2CX5E1801 | AM32: =+'Pegar Archivo Tienda Nube'!AM19 -> 0196d6bc-de4f-7dc4-bc24-62cbca4e3934 | AN32: =+'Pegar Archivo Tienda Nube'!AN19 -> 1709609598 | AO32: =+'Pegar Archivo Tienda Nube'!AO19 -> Sí | AP32: =+'Pegar Archivo Tienda Nube'!AP19 -> 0 | AQ32: =+'Pegar Archivo Tienda Nube'!AQ19 -> 0 | AR32: =+'Pegar Archivo Tienda Nube'!AR19 -> 0 | AS32: 11
A33: =+'Pegar Archivo Tienda Nube'!A20 -> 116 | B33: =+'Pegar Archivo Tienda Nube'!B20 -> celestevalltondre@gmail.com | C33: 45899 | D33: =+'Pegar Archivo Tienda Nube'!D20 -> 0 | E33: =+'Pegar Archivo Tienda Nube'!E20 -> 0 | F33: =+'Pegar Archivo Tienda Nube'!F20 -> 0 | G33: =IF('Pegar Archivo Tienda Nube'!G20="ARS","PS","PS") -> PS | H33: =+'Pegar Archivo Tienda Nube'!H20 -> 0 | I33: =+'Pegar Archivo Tienda Nube'!I20 -> 0 | J33: =+'Pegar Archivo Tienda Nube'!J20 -> 0 | K33: =+'Pegar Archivo Tienda Nube'!K20 -> 0 | L33: =+'Pegar Archivo Tienda Nube'!L20 -> 0 | M33: =+'Pegar Archivo Tienda Nube'!M20 -> 0 | N33: =+'Pegar Archivo Tienda Nube'!N20 -> 0 | O33: =+'Pegar Archivo Tienda Nube'!O20 -> 0 | ... Z33: =+'Pegar Archivo Tienda Nube'!Z20 -> 0 | AA33: =+'Pegar Archivo Tienda Nube'!AB20 -> 0 | AC33: =+'Pegar Archivo Tienda Nube'!AC20 -> 0 | AD33: =+'Pegar Archivo Tienda Nube'!AD20 -> 0 | AE33: =+C33 -> 45899 | AF33: =+'Pegar Archivo Tienda Nube'!AF20 -> 0 | AG33: =+'Pegar Archivo Tienda Nube'!AG20 -> Riñonera Siena (Negro) | AH33: =+'Pegar Archivo Tienda Nube'!AH20 -> 24300 | AI33: =+'Pegar Archivo Tienda Nube'!AI20 -> 1 | AJ33: LZSBK12WH | AK33: =+'Pegar Archivo Tienda Nube'!AK20 -> 0 | AL33: =+'Pegar Archivo Tienda Nube'!AL20 -> 0 | AM33: =+'Pegar Archivo Tienda Nube'!AM20 -> 0 | AN33: =+'Pegar Archivo Tienda Nube'!AN20 -> 0 | AO33: =+'Pegar Archivo Tienda Nube'!AO20 -> Sí | AP33: =+'Pegar Archivo Tienda Nube'!AP20 -> 0 | AQ33: =+'Pegar Archivo Tienda Nube'!AQ20 -> 0 | AR33: =+'Pegar Archivo Tienda Nube'!AR20 -> 0 | AS33: 11
A34: =+'Pegar Archivo Tienda Nube'!A21 -> 117 | B34: =+'Pegar Archivo Tienda Nube'!B21 -> Ledezmajacqueline777@gmail.com | C34: 45899 | D34: =+'Pegar Archivo Tienda Nube'!D21 -> Abierta | E34: =+'Pegar Archivo Tienda Nube'!E21 -> Recibido | F34: =+'Pegar Archivo Tienda Nube'!F21 -> Entregado | G34: =IF('Pegar Archivo Tienda Nube'!G21="ARS","PS","PS") -> PS | H34: =+'Pegar Archivo Tienda Nube'!H21 -> 61912 | I34: =+'Pegar Archivo Tienda Nube'!I21 -> 0 | J34: =+'Pegar Archivo Tienda Nube'!J21 -> 0 | K34: =+'Pegar Archivo Tienda Nube'!K21 -> 61912 | L34: =+'Pegar Archivo Tienda Nube'!L21 -> Jacqueline ledesma | M34: =+'Pegar Archivo Tienda Nube'!M21 -> 46076602 | N34: =+'Pegar Archivo Tienda Nube'!N21 -> 541138322608 | O34: =+'Pegar Archivo Tienda Nube'!O21 -> Jacqueline ledesma | ... Z34: =+'Pegar Archivo Tienda Nube'!Z21 -> Pago Nube | AA34: =+'Pegar Archivo Tienda Nube'!AB21 -> 0 | AC34: =+'Pegar Archivo Tienda Nube'!AC21 -> Envío a mí trabajo referencia: Restaurante Manus. | AD34: =+'Pegar Archivo Tienda Nube'!AD21 -> 0 | AE34: =+C34 -> 45899 | AF34: =+'Pegar Archivo Tienda Nube'!AF21 -> 45799 | AG34: =+'Pegar Archivo Tienda Nube'!AG21 -> Mochila Cristal (Negro) | AH34: =+'Pegar Archivo Tienda Nube'!AH21 -> 41310 | AI34: =+'Pegar Archivo Tienda Nube'!AI21 -> 1 | AJ34: LZSBK12WH | AK34: =+'Pegar Archivo Tienda Nube'!AK21 -> Móvil | AL34: =+'Pegar Archivo Tienda Nube'!AL21 -> 197818G59351GGC501 | AM34: =+'Pegar Archivo Tienda Nube'!AM21 -> 0196d9d8-dede-7773-b679-1000fe65c40e | AN34: =+'Pegar Archivo Tienda Nube'!AN21 -> 1709934791 | AO34: =+'Pegar Archivo Tienda Nube'!AO21 -> Sí | AP34: =+'Pegar Archivo Tienda Nube'!AP21 -> 0 | AQ34: =+'Pegar Archivo Tienda Nube'!AQ21 -> 0 | AR34: =+'Pegar Archivo Tienda Nube'!AR21 -> 0 | AS34: 11
A35: =+'Pegar Archivo Tienda Nube'!A22 -> 117 | B35: =+'Pegar Archivo Tienda Nube'!B22 -> Ledezmajacqueline777@gmail.com | C35: 45901 | D35: =+'Pegar Archivo Tienda Nube'!D22 -> 0 | E35: =+'Pegar Archivo Tienda Nube'!E22 -> 0 | F35: =+'Pegar Archivo Tienda Nube'!F22 -> 0 | G35: =IF('Pegar Archivo Tienda Nube'!G22="ARS","PS","PS") -> PS | H35: =+'Pegar Archivo Tienda Nube'!H22 -> 0 | I35: =+'Pegar Archivo Tienda Nube'!I22 -> 0 | J35: =+'Pegar Archivo Tienda Nube'!J22 -> 0 | K35: =+'Pegar Archivo Tienda Nube'!K22 -> 0 | L35: =+'Pegar Archivo Tienda Nube'!L22 -> 0 | M35: =+'Pegar Archivo Tienda Nube'!M22 -> 0 | N35: =+'Pegar Archivo Tienda Nube'!N22 -> 0 | O35: =+'Pegar Archivo Tienda Nube'!O22 -> 0 | ... Z35: =+'Pegar Archivo Tienda Nube'!Z22 -> 0 | AA35: =+'Pegar Archivo Tienda Nube'!AB22 -> 0 | AC35: =+'Pegar Archivo Tienda Nube'!AC22 -> 0 | AD35: =+'Pegar Archivo Tienda Nube'!AD22 -> 0 | AE35: =+C35 -> 45901 | AF35: =+'Pegar Archivo Tienda Nube'!AF22 -> 0 | AG35: =+'Pegar Archivo Tienda Nube'!AG22 -> Riñonera Nube (Negro) | AH35: =+'Pegar Archivo Tienda Nube'!AH22 -> 20602 | AI35: =+'Pegar Archivo Tienda Nube'!AI22 -> 1 | AJ35: LZSBK12WH | AK35: =+'Pegar Archivo Tienda Nube'!AK22 -> 0 | AL35: =+'Pegar Archivo Tienda Nube'!AL22 -> 0 | AM35: =+'Pegar Archivo Tienda Nube'!AM22 -> 0 | AN35: =+'Pegar Archivo Tienda Nube'!AN22 -> 0 | AO35: =+'Pegar Archivo Tienda Nube'!AO22 -> Sí | AP35: =+'Pegar Archivo Tienda Nube'!AP22 -> 0 | AQ35: =+'Pegar Archivo Tienda Nube'!AQ22 -> 0 | AR35: =+'Pegar Archivo Tienda Nube'!AR22 -> 0 | AS35: 11
... A43: =+'Pegar Archivo Tienda Nube'!A30 -> 121 | B43: =+'Pegar Archivo Tienda Nube'!B30 -> santiyanina10@gmail.com | C43: 45909 | D43: =+'Pegar Archivo Tienda Nube'!D30 -> 0 | E43: =+'Pegar Archivo Tienda Nube'!E30 -> 0 | F43: =+'Pegar Archivo Tienda Nube'!F30 -> 0 | G43: =IF('Pegar Archivo Tienda Nube'!G30="ARS","PS","PS") -> PS | H43: =+'Pegar Archivo Tienda Nube'!H30 -> 0 | I43: =+'Pegar Archivo Tienda Nube'!I30 -> 0 | J43: =+'Pegar Archivo Tienda Nube'!J30 -> 0 | K43: =+'Pegar Archivo Tienda Nube'!K30 -> 0 | L43: =+'Pegar Archivo Tienda Nube'!L30 -> 0 | M43: =+'Pegar Archivo Tienda Nube'!M30 -> 0 | N43: =+'Pegar Archivo Tienda Nube'!N30 -> 0 | O43: =+'Pegar Archivo Tienda Nube'!O30 -> 0 | ... Z43: =+'Pegar Archivo Tienda Nube'!Z30 -> 0 | AA43: =+'Pegar Archivo Tienda Nube'!AB30 -> 0 | AC43: =+'Pegar Archivo Tienda Nube'!AC30 -> 0 | AD43: =+'Pegar Archivo Tienda Nube'!AD30 -> 0 | AE43: =+C43 -> 45909 | AF43: =+'Pegar Archivo Tienda Nube'!AF30 -> 0 | AG43: =+'Pegar Archivo Tienda Nube'!AG30 -> Riñonera Nube (Negro) | AH43: =+'Pegar Archivo Tienda Nube'!AH30 -> 20602 | AI43: =+'Pegar Archivo Tienda Nube'!AI30 -> 1 | AJ43: LZSBK12WH | AK43: =+'Pegar Archivo Tienda Nube'!AK30 -> 0 | AL43: =+'Pegar Archivo Tienda Nube'!AL30 -> 0 | AM43: =+'Pegar Archivo Tienda Nube'!AM30 -> 0 | AN43: =+'Pegar Archivo Tienda Nube'!AN30 -> 0 | AO43: =+'Pegar Archivo Tienda Nube'!AO30 -> Sí | AP43: =+'Pegar Archivo Tienda Nube'!AP30 -> 0 | AQ43: =+'Pegar Archivo Tienda Nube'!AQ30 -> 0 | AR43: =+'Pegar Archivo Tienda Nube'!AR30 -> 0 | AS43: 11
A44: =+'Pegar Archivo Tienda Nube'!A32 -> 0 | B44: =+'Pegar Archivo Tienda Nube'!B32 -> 0 | C44: 45911 | D44: =+'Pegar Archivo Tienda Nube'!D32 -> 0 | E44: =+'Pegar Archivo Tienda Nube'!E32 -> 0 | F44: =+'Pegar Archivo Tienda Nube'!F32 -> 0 | G44: =IF('Pegar Archivo Tienda Nube'!G32="ARS","PS","PS") -> PS | H44: =+'Pegar Archivo Tienda Nube'!H32 -> 0 | I44: =+'Pegar Archivo Tienda Nube'!I32 -> 0 | J44: =+'Pegar Archivo Tienda Nube'!J32 -> 0 | K44: =+'Pegar Archivo Tienda Nube'!K32 -> 0 | L44: =+'Pegar Archivo Tienda Nube'!L32 -> 0 | M44: =+'Pegar Archivo Tienda Nube'!M32 -> 0 | N44: =+'Pegar Archivo Tienda Nube'!N32 -> 0 | O44: =+'Pegar Archivo Tienda Nube'!O32 -> 0 | ... Z44: =+'Pegar Archivo Tienda Nube'!Z32 -> 0 | AA44: =+'Pegar Archivo Tienda Nube'!AB32 -> 0 | AC44: =+'Pegar Archivo Tienda Nube'!AC32 -> 0 | AD44: =+'Pegar Archivo Tienda Nube'!AD32 -> 0 | AE44: =+C44 -> 45911 | AF44: =+'Pegar Archivo Tienda Nube'!AF32 -> 0 | AG44: =+'Pegar Archivo Tienda Nube'!AG32 -> 0 | AH44: =+'Pegar Archivo Tienda Nube'!AH32 -> 0 | AI44: =+'Pegar Archivo Tienda Nube'!AI32 -> 0 | AJ44: LZSBK12WH | AK44: =+'Pegar Archivo Tienda Nube'!AK32 -> 0 | AL44: =+'Pegar Archivo Tienda Nube'!AL32 -> 0 | AM44: =+'Pegar Archivo Tienda Nube'!AM32 -> 0 | AN44: =+'Pegar Archivo Tienda Nube'!AN32 -> 0 | AO44: =+'Pegar Archivo Tienda Nube'!AO32 -> 0 | AP44: =+'Pegar Archivo Tienda Nube'!AP32 -> 0 | AQ44: =+'Pegar Archivo Tienda Nube'!AQ32 -> 0 | AR44: =+'Pegar Archivo Tienda Nube'!AR32 -> 0 | AS44: 11
A45: =+'Pegar Archivo Tienda Nube'!A33 -> 0 | B45: =+'Pegar Archivo Tienda Nube'!B33 -> 0 | C45: 45912 | D45: =+'Pegar Archivo Tienda Nube'!D33 -> 0 | E45: =+'Pegar Archivo Tienda Nube'!E33 -> 0 | F45: =+'Pegar Archivo Tienda Nube'!F33 -> 0 | G45: =IF('Pegar Archivo Tienda Nube'!G33="ARS","PS","PS") -> PS | H45: =+'Pegar Archivo Tienda Nube'!H33 -> 0 | I45: =+'Pegar Archivo Tienda Nube'!I33 -> 0 | J45: =+'Pegar Archivo Tienda Nube'!J33 -> 0 | K45: =+'Pegar Archivo Tienda Nube'!K33 -> 0 | L45: =+'Pegar Archivo Tienda Nube'!L33 -> 0 | M45: =+'Pegar Archivo Tienda Nube'!M33 -> 0 | N45: =+'Pegar Archivo Tienda Nube'!N33 -> 0 | O45: =+'Pegar Archivo Tienda Nube'!O33 -> 0 | ... Z45: =+'Pegar Archivo Tienda Nube'!Z33 -> 0 | AA45: =+'Pegar Archivo Tienda Nube'!AB33 -> 0 | AC45: =+'Pegar Archivo Tienda Nube'!AC33 -> 0 | AD45: =+'Pegar Archivo Tienda Nube'!AD33 -> 0 | AE45: =+C45 -> 45912 | AF45: =+'Pegar Archivo Tienda Nube'!AF33 -> 0 | AG45: =+'Pegar Archivo Tienda Nube'!AG33 -> 0 | AH45: =+'Pegar Archivo Tienda Nube'!AH33 -> 0 | AI45: =+'Pegar Archivo Tienda Nube'!AI33 -> 0 | AJ45: LZSBK12WH | AK45: =+'Pegar Archivo Tienda Nube'!AK33 -> 0 | AL45: =+'Pegar Archivo Tienda Nube'!AL33 -> 0 | AM45: =+'Pegar Archivo Tienda Nube'!AM33 -> 0 | AN45: =+'Pegar Archivo Tienda Nube'!AN33 -> 0 | AO45: =+'Pegar Archivo Tienda Nube'!AO33 -> 0 | AP45: =+'Pegar Archivo Tienda Nube'!AP33 -> 0 | AQ45: =+'Pegar Archivo Tienda Nube'!AQ33 -> 0 | AR45: =+'Pegar Archivo Tienda Nube'!AR33 -> 0 | AS45: 11
A46: =+'Pegar Archivo Tienda Nube'!A34 -> 0 | B46: =+'Pegar Archivo Tienda Nube'!B34 -> 0 | C46: 45913 | D46: =+'Pegar Archivo Tienda Nube'!D34 -> 0 | E46: =+'Pegar Archivo Tienda Nube'!E34 -> 0 | F46: =+'Pegar Archivo Tienda Nube'!F34 -> 0 | G46: =IF('Pegar Archivo Tienda Nube'!G34="ARS","PS","PS") -> PS | H46: =+'Pegar Archivo Tienda Nube'!H34 -> 0 | I46: =+'Pegar Archivo Tienda Nube'!I34 -> 0 | J46: =+'Pegar Archivo Tienda Nube'!J34 -> 0 | K46: =+'Pegar Archivo Tienda Nube'!K34 -> 0 | L46: =+'Pegar Archivo Tienda Nube'!L34 -> 0 | M46: =+'Pegar Archivo Tienda Nube'!M34 -> 0 | N46: =+'Pegar Archivo Tienda Nube'!N34 -> 0 | O46: =+'Pegar Archivo Tienda Nube'!O34 -> 0 | ... Z46: =+'Pegar Archivo Tienda Nube'!Z34 -> 0 | AA46: =+'Pegar Archivo Tienda Nube'!AB34 -> 0 | AC46: =+'Pegar Archivo Tienda Nube'!AC34 -> 0 | AD46: =+'Pegar Archivo Tienda Nube'!AD34 -> 0 | AE46: =+C46 -> 45913 | AF46: =+'Pegar Archivo Tienda Nube'!AF34 -> 0 | AG46: =+'Pegar Archivo Tienda Nube'!AG34 -> 0 | AH46: =+'Pegar Archivo Tienda Nube'!AH34 -> 0 | AI46: =+'Pegar Archivo Tienda Nube'!AI34 -> 0 | AJ46: LZSBK12WH | AK46: =+'Pegar Archivo Tienda Nube'!AK34 -> 0 | AL46: =+'Pegar Archivo Tienda Nube'!AL34 -> 0 | AM46: =+'Pegar Archivo Tienda Nube'!AM34 -> 0 | AN46: =+'Pegar Archivo Tienda Nube'!AN34 -> 0 | AO46: =+'Pegar Archivo Tienda Nube'!AO34 -> 0 | AP46: =+'Pegar Archivo Tienda Nube'!AP34 -> 0 | AQ46: =+'Pegar Archivo Tienda Nube'!AQ34 -> 0 | AR46: =+'Pegar Archivo Tienda Nube'!AR34 -> 0 | AS46: 11
A47: =+'Pegar Archivo Tienda Nube'!A35 -> 0 | B47: =+'Pegar Archivo Tienda Nube'!B35 -> 0 | C47: 45914 | D47: =+'Pegar Archivo Tienda Nube'!D35 -> 0 | E47: =+'Pegar Archivo Tienda Nube'!E35 -> 0 | F47: =+'Pegar Archivo Tienda Nube'!F35 -> 0 | G47: =IF('Pegar Archivo Tienda Nube'!G35="ARS","PS","PS") -> PS | H47: =+'Pegar Archivo Tienda Nube'!H35 -> 0 | I47: =+'Pegar Archivo Tienda Nube'!I35 -> 0 | J47: =+'Pegar Archivo Tienda Nube'!J35 -> 0 | K47: =+'Pegar Archivo Tienda Nube'!K35 -> 0 | L47: =+'Pegar Archivo Tienda Nube'!L35 -> 0 | M47: =+'Pegar Archivo Tienda Nube'!M35 -> 0 | N47: =+'Pegar Archivo Tienda Nube'!N35 -> 0 | O47: =+'Pegar Archivo Tienda Nube'!O35 -> 0 | ... Z47: =+'Pegar Archivo Tienda Nube'!Z35 -> 0 | AA47: =+'Pegar Archivo Tienda Nube'!AB35 -> 0 | AC47: =+'Pegar Archivo Tienda Nube'!AC35 -> 0 | AD47: =+'Pegar Archivo Tienda Nube'!AD35 -> 0 | AE47: =+C47 -> 45914 | AF47: =+'Pegar Archivo Tienda Nube'!AF35 -> 0 | AG47: =+'Pegar Archivo Tienda Nube'!AG35 -> 0 | AH47: =+'Pegar Archivo Tienda Nube'!AH35 -> 0 | AI47: =+'Pegar Archivo Tienda Nube'!AI35 -> 0 | AJ47: LZSBK12WH | AK47: =+'Pegar Archivo Tienda Nube'!AK35 -> 0 | AL47: =+'Pegar Archivo Tienda Nube'!AL35 -> 0 | AM47: =+'Pegar Archivo Tienda Nube'!AM35 -> 0 | AN47: =+'Pegar Archivo Tienda Nube'!AN35 -> 0 | AO47: =+'Pegar Archivo Tienda Nube'!AO35 -> 0 | AP47: =+'Pegar Archivo Tienda Nube'!AP35 -> 0 | AQ47: =+'Pegar Archivo Tienda Nube'!AQ35 -> 0 | AR47: =+'Pegar Archivo Tienda Nube'!AR35 -> 0 | AS47: 11
A48: =+'Pegar Archivo Tienda Nube'!A36 -> 0 | B48: =+'Pegar Archivo Tienda Nube'!B36 -> 0 | C48: 45915 | D48: =+'Pegar Archivo Tienda Nube'!D36 -> 0 | E48: =+'Pegar Archivo Tienda Nube'!E36 -> 0 | F48: =+'Pegar Archivo Tienda Nube'!F36 -> 0 | G48: =IF('Pegar Archivo Tienda Nube'!G36="ARS","PS","PS") -> PS | H48: =+'Pegar Archivo Tienda Nube'!H36 -> 0 | I48: =+'Pegar Archivo Tienda Nube'!I36 -> 0 | J48: =+'Pegar Archivo Tienda Nube'!J36 -> 0 | K48: =+'Pegar Archivo Tienda Nube'!K36 -> 0 | L48: =+'Pegar Archivo Tienda Nube'!L36 -> 0 | M48: =+'Pegar Archivo Tienda Nube'!M36 -> 0 | N48: =+'Pegar Archivo Tienda Nube'!N36 -> 0 | O48: =+'Pegar Archivo Tienda Nube'!O36 -> 0 | ... Z48: =+'Pegar Archivo Tienda Nube'!Z36 -> 0 | AA48: =+'Pegar Archivo Tienda Nube'!AB36 -> 0 | AC48: =+'Pegar Archivo Tienda Nube'!AC36 -> 0 | AD48: =+'Pegar Archivo Tienda Nube'!AD36 -> 0 | AE48: =+C48 -> 45915 | AF48: =+'Pegar Archivo Tienda Nube'!AF36 -> 0 | AG48: =+'Pegar Archivo Tienda Nube'!AG36 -> 0 | AH48: =+'Pegar Archivo Tienda Nube'!AH36 -> 0 | AI48: =+'Pegar Archivo Tienda Nube'!AI36 -> 0 | AJ48: LZSBK12WH | AK48: =+'Pegar Archivo Tienda Nube'!AK36 -> 0 | AL48: =+'Pegar Archivo Tienda Nube'!AL36 -> 0 | AM48: =+'Pegar Archivo Tienda Nube'!AM36 -> 0 | AN48: =+'Pegar Archivo Tienda Nube'!AN36 -> 0 | AO48: =+'Pegar Archivo Tienda Nube'!AO36 -> 0 | AP48: =+'Pegar Archivo Tienda Nube'!AP36 -> 0 | AQ48: =+'Pegar Archivo Tienda Nube'!AQ36 -> 0 | AR48: =+'Pegar Archivo Tienda Nube'!AR36 -> 0 | AS48: 11
A49: =+'Pegar Archivo Tienda Nube'!A37 -> 0 | B49: =+'Pegar Archivo Tienda Nube'!B37 -> 0 | C49: 45916 | D49: =+'Pegar Archivo Tienda Nube'!D37 -> 0 | E49: =+'Pegar Archivo Tienda Nube'!E37 -> 0 | F49: =+'Pegar Archivo Tienda Nube'!F37 -> 0 | G49: =IF('Pegar Archivo Tienda Nube'!G37="ARS","PS","PS") -> PS | H49: =+'Pegar Archivo Tienda Nube'!H37 -> 0 | I49: =+'Pegar Archivo Tienda Nube'!I37 -> 0 | J49: =+'Pegar Archivo Tienda Nube'!J37 -> 0 | K49: =+'Pegar Archivo Tienda Nube'!K37 -> 0 | L49: =+'Pegar Archivo Tienda Nube'!L37 -> 0 | M49: =+'Pegar Archivo Tienda Nube'!M37 -> 0 | N49: =+'Pegar Archivo Tienda Nube'!N37 -> 0 | O49: =+'Pegar Archivo Tienda Nube'!O37 -> 0 | ... Z49: =+'Pegar Archivo Tienda Nube'!Z37 -> 0 | AA49: =+'Pegar Archivo Tienda Nube'!AB37 -> 0 | AC49: =+'Pegar Archivo Tienda Nube'!AC37 -> 0 | AD49: =+'Pegar Archivo Tienda Nube'!AD37 -> 0 | AE49: =+C49 -> 45916 | AF49: =+'Pegar Archivo Tienda Nube'!AF37 -> 0 | AG49: =+'Pegar Archivo Tienda Nube'!AG37 -> 0 | AH49: =+'Pegar Archivo Tienda Nube'!AH37 -> 0 | AI49: =+'Pegar Archivo Tienda Nube'!AI37 -> 0 | AJ49: LZSBK12WH | AK49: =+'Pegar Archivo Tienda Nube'!AK37 -> 0 | AL49: =+'Pegar Archivo Tienda Nube'!AL37 -> 0 | AM49: =+'Pegar Archivo Tienda Nube'!AM37 -> 0 | AN49: =+'Pegar Archivo Tienda Nube'!AN37 -> 0 | AO49: =+'Pegar Archivo Tienda Nube'!AO37 -> 0 | AP49: =+'Pegar Archivo Tienda Nube'!AP37 -> 0 | AQ49: =+'Pegar Archivo Tienda Nube'!AQ37 -> 0 | AR49: =+'Pegar Archivo Tienda Nube'!AR37 -> 0 | AS49: 11
A50: =+'Pegar Archivo Tienda Nube'!A38 -> 0 | B50: =+'Pegar Archivo Tienda Nube'!B38 -> 0 | C50: 45917 | D50: =+'Pegar Archivo Tienda Nube'!D38 -> 0 | E50: =+'Pegar Archivo Tienda Nube'!E38 -> 0 | F50: =+'Pegar Archivo Tienda Nube'!F38 -> 0 | G50: =IF('Pegar Archivo Tienda Nube'!G38="ARS","PS","PS") -> PS | H50: =+'Pegar Archivo Tienda Nube'!H38 -> 0 | I50: =+'Pegar Archivo Tienda Nube'!I38 -> 0 | J50: =+'Pegar Archivo Tienda Nube'!J38 -> 0 | K50: =+'Pegar Archivo Tienda Nube'!K38 -> 0 | L50: =+'Pegar Archivo Tienda Nube'!L38 -> 0 | M50: =+'Pegar Archivo Tienda Nube'!M38 -> 0 | N50: =+'Pegar Archivo Tienda Nube'!N38 -> 0 | O50: =+'Pegar Archivo Tienda Nube'!O38 -> 0 | ... Z50: =+'Pegar Archivo Tienda Nube'!Z38 -> 0 | AA50: =+'Pegar Archivo Tienda Nube'!AB38 -> 0 | AC50: =+'Pegar Archivo Tienda Nube'!AC38 -> 0 | AD50: =+'Pegar Archivo Tienda Nube'!AD38 -> 0 | AE50: =+C50 -> 45917 | AF50: =+'Pegar Archivo Tienda Nube'!AF38 -> 0 | AG50: =+'Pegar Archivo Tienda Nube'!AG38 -> 0 | AH50: =+'Pegar Archivo Tienda Nube'!AH38 -> 0 | AI50: =+'Pegar Archivo Tienda Nube'!AI38 -> 0 | AJ50: LZSBK12WH | AK50: =+'Pegar Archivo Tienda Nube'!AK38 -> 0 | AL50: =+'Pegar Archivo Tienda Nube'!AL38 -> 0 | AM50: =+'Pegar Archivo Tienda Nube'!AM38 -> 0 | AN50: =+'Pegar Archivo Tienda Nube'!AN38 -> 0 | AO50: =+'Pegar Archivo Tienda Nube'!AO38 -> 0 | AP50: =+'Pegar Archivo Tienda Nube'!AP38 -> 0 | AQ50: =+'Pegar Archivo Tienda Nube'!AQ38 -> 0 | AR50: =+'Pegar Archivo Tienda Nube'!AR38 -> 0 | AS50: 11
A51: =+'Pegar Archivo Tienda Nube'!A39 -> 0 | B51: =+'Pegar Archivo Tienda Nube'!B39 -> 0 | C51: 45918 | D51: =+'Pegar Archivo Tienda Nube'!D39 -> 0 | E51: =+'Pegar Archivo Tienda Nube'!E39 -> 0 | F51: =+'Pegar Archivo Tienda Nube'!F39 -> 0 | G51: =IF('Pegar Archivo Tienda Nube'!G39="ARS","PS","PS") -> PS | H51: =+'Pegar Archivo Tienda Nube'!H39 -> 0 | I51: =+'Pegar Archivo Tienda Nube'!I39 -> 0 | J51: =+'Pegar Archivo Tienda Nube'!J39 -> 0 | K51: =+'Pegar Archivo Tienda Nube'!K39 -> 0 | L51: =+'Pegar Archivo Tienda Nube'!L39 -> 0 | M51: =+'Pegar Archivo Tienda Nube'!M39 -> 0 | N51: =+'Pegar Archivo Tienda Nube'!N39 -> 0 | O51: =+'Pegar Archivo Tienda Nube'!O39 -> 0 | ... Z51: =+'Pegar Archivo Tienda Nube'!Z39 -> 0 | AA51: =+'Pegar Archivo Tienda Nube'!AB39 -> 0 | AC51: =+'Pegar Archivo Tienda Nube'!AC39 -> 0 | AD51: =+'Pegar Archivo Tienda Nube'!AD39 -> 0 | AE51: =+C51 -> 45918 | AF51: =+'Pegar Archivo Tienda Nube'!AF39 -> 0 | AG51: =+'Pegar Archivo Tienda Nube'!AG39 -> 0 | AH51: =+'Pegar Archivo Tienda Nube'!AH39 -> 0 | AI51: =+'Pegar Archivo Tienda Nube'!AI39 -> 0 | AJ51: LZSBK12WH | AK51: =+'Pegar Archivo Tienda Nube'!AK39 -> 0 | AL51: =+'Pegar Archivo Tienda Nube'!AL39 -> 0 | AM51: =+'Pegar Archivo Tienda Nube'!AM39 -> 0 | AN51: =+'Pegar Archivo Tienda Nube'!AN39 -> 0 | AO51: =+'Pegar Archivo Tienda Nube'!AO39 -> 0 | AP51: =+'Pegar Archivo Tienda Nube'!AP39 -> 0 | AQ51: =+'Pegar Archivo Tienda Nube'!AQ39 -> 0 | AR51: =+'Pegar Archivo Tienda Nube'!AR39 -> 0 | AS51: 11
A52: =+'Pegar Archivo Tienda Nube'!A40 -> 0 | B52: =+'Pegar Archivo Tienda Nube'!B40 -> 0 | C52: 45919 | D52: =+'Pegar Archivo Tienda Nube'!D40 -> 0 | E52: =+'Pegar Archivo Tienda Nube'!E40 -> 0 | F52: =+'Pegar Archivo Tienda Nube'!F40 -> 0 | G52: =IF('Pegar Archivo Tienda Nube'!G40="ARS","PS","PS") -> PS | H52: =+'Pegar Archivo Tienda Nube'!H40 -> 0 | I52: =+'Pegar Archivo Tienda Nube'!I40 -> 0 | J52: =+'Pegar Archivo Tienda Nube'!J40 -> 0 | K52: =+'Pegar Archivo Tienda Nube'!K40 -> 0 | L52: =+'Pegar Archivo Tienda Nube'!L40 -> 0 | M52: =+'Pegar Archivo Tienda Nube'!M40 -> 0 | N52: =+'Pegar Archivo Tienda Nube'!N40 -> 0 | O52: =+'Pegar Archivo Tienda Nube'!O40 -> 0 | ... Z52: =+'Pegar Archivo Tienda Nube'!Z40 -> 0 | AA52: =+'Pegar Archivo Tienda Nube'!AB40 -> 0 | AC52: =+'Pegar Archivo Tienda Nube'!AC40 -> 0 | AD52: =+'Pegar Archivo Tienda Nube'!AD40 -> 0 | AE52: =+C52 -> 45919 | AF52: =+'Pegar Archivo Tienda Nube'!AF40 -> 0 | AG52: =+'Pegar Archivo Tienda Nube'!AG40 -> 0 | AH52: =+'Pegar Archivo Tienda Nube'!AH40 -> 0 | AI52: =+'Pegar Archivo Tienda Nube'!AI40 -> 0 | AJ52: LZSBK12WH | AK52: =+'Pegar Archivo Tienda Nube'!AK40 -> 0 | AL52: =+'Pegar Archivo Tienda Nube'!AL40 -> 0 | AM52: =+'Pegar Archivo Tienda Nube'!AM40 -> 0 | AN52: =+'Pegar Archivo Tienda Nube'!AN40 -> 0 | AO52: =+'Pegar Archivo Tienda Nube'!AO40 -> 0 | AP52: =+'Pegar Archivo Tienda Nube'!AP40 -> 0 | AQ52: =+'Pegar Archivo Tienda Nube'!AQ40 -> 0 | AR52: =+'Pegar Archivo Tienda Nube'!AR40 -> 0 | AS52: 11
A53: =+'Pegar Archivo Tienda Nube'!A41 -> 0 | B53: =+'Pegar Archivo Tienda Nube'!B41 -> 0 | C53: 45920 | D53: =+'Pegar Archivo Tienda Nube'!D41 -> 0 | E53: =+'Pegar Archivo Tienda Nube'!E41 -> 0 | F53: =+'Pegar Archivo Tienda Nube'!F41 -> 0 | G53: =IF('Pegar Archivo Tienda Nube'!G41="ARS","PS","PS") -> PS | H53: =+'Pegar Archivo Tienda Nube'!H41 -> 0 | I53: =+'Pegar Archivo Tienda Nube'!I41 -> 0 | J53: =+'Pegar Archivo Tienda Nube'!J41 -> 0 | K53: =+'Pegar Archivo Tienda Nube'!K41 -> 0 | L53: =+'Pegar Archivo Tienda Nube'!L41 -> 0 | M53: =+'Pegar Archivo Tienda Nube'!M41 -> 0 | N53: =+'Pegar Archivo Tienda Nube'!N41 -> 0 | O53: =+'Pegar Archivo Tienda Nube'!O41 -> 0 | ... Z53: =+'Pegar Archivo Tienda Nube'!Z41 -> 0 | AA53: =+'Pegar Archivo Tienda Nube'!AB41 -> 0 | AC53: =+'Pegar Archivo Tienda Nube'!AC41 -> 0 | AD53: =+'Pegar Archivo Tienda Nube'!AD41 -> 0 | AE53: =+C53 -> 45920 | AF53: =+'Pegar Archivo Tienda Nube'!AF41 -> 0 | AG53: =+'Pegar Archivo Tienda Nube'!AG41 -> 0 | AH53: =+'Pegar Archivo Tienda Nube'!AH41 -> 0 | AI53: =+'Pegar Archivo Tienda Nube'!AI41 -> 0 | AJ53: LZSBK12WH | AK53: =+'Pegar Archivo Tienda Nube'!AK41 -> 0 | AL53: =+'Pegar Archivo Tienda Nube'!AL41 -> 0 | AM53: =+'Pegar Archivo Tienda Nube'!AM41 -> 0 | AN53: =+'Pegar Archivo Tienda Nube'!AN41 -> 0 | AO53: =+'Pegar Archivo Tienda Nube'!AO41 -> 0 | AP53: =+'Pegar Archivo Tienda Nube'!AP41 -> 0 | AQ53: =+'Pegar Archivo Tienda Nube'!AQ41 -> 0 | AR53: =+'Pegar Archivo Tienda Nube'!AR41 -> 0 | AS53: 11
A54: =+'Pegar Archivo Tienda Nube'!A42 -> 0 | B54: =+'Pegar Archivo Tienda Nube'!B42 -> 0 | C54: 45921 | D54: =+'Pegar Archivo Tienda Nube'!D42 -> 0 | E54: =+'Pegar Archivo Tienda Nube'!E42 -> 0 | F54: =+'Pegar Archivo Tienda Nube'!F42 -> 0 | G54: =IF('Pegar Archivo Tienda Nube'!G42="ARS","PS","PS") -> PS | H54: =+'Pegar Archivo Tienda Nube'!H42 -> 0 | I54: =+'Pegar Archivo Tienda Nube'!I42 -> 0 | J54: =+'Pegar Archivo Tienda Nube'!J42 -> 0 | K54: =+'Pegar Archivo Tienda Nube'!K42 -> 0 | L54: =+'Pegar Archivo Tienda Nube'!L42 -> 0 | M54: =+'Pegar Archivo Tienda Nube'!M42 -> 0 | N54: =+'Pegar Archivo Tienda Nube'!N42 -> 0 | O54: =+'Pegar Archivo Tienda Nube'!O42 -> 0 | ... Z54: =+'Pegar Archivo Tienda Nube'!Z42 -> 0 | AA54: =+'Pegar Archivo Tienda Nube'!AB42 -> 0 | AC54: =+'Pegar Archivo Tienda Nube'!AC42 -> 0 | AD54: =+'Pegar Archivo Tienda Nube'!AD42 -> 0 | AE54: =+C54 -> 45921 | AF54: =+'Pegar Archivo Tienda Nube'!AF42 -> 0 | AG54: =+'Pegar Archivo Tienda Nube'!AG42 -> 0 | AH54: =+'Pegar Archivo Tienda Nube'!AH42 -> 0 | AI54: =+'Pegar Archivo Tienda Nube'!AI42 -> 0 | AJ54: LZSBK12WH | AK54: =+'Pegar Archivo Tienda Nube'!AK42 -> 0 | AL54: =+'Pegar Archivo Tienda Nube'!AL42 -> 0 | AM54: =+'Pegar Archivo Tienda Nube'!AM42 -> 0 | AN54: =+'Pegar Archivo Tienda Nube'!AN42 -> 0 | AO54: =+'Pegar Archivo Tienda Nube'!AO42 -> 0 | AP54: =+'Pegar Archivo Tienda Nube'!AP42 -> 0 | AQ54: =+'Pegar Archivo Tienda Nube'!AQ42 -> 0 | AR54: =+'Pegar Archivo Tienda Nube'!AR42 -> 0 | AS54: 11
...
