Workbook

Sheet Ubicaciones
A1: Ubicaciones | N1: Dato Obligatorio
C5: 1 | D5: 2 | E5: 3 | F5: 4 | G5: 5 | H5: 6 | I5: 7 | J5: 8 | K5: 9
E6: 0: No
E7: 1: Si
C12: Código | D12: Descripción | E12: Habilitado | F12: Código de Barras | G12: Peso Bruto Máximo | H12: Volumen Máximo | I12: Bultos Máximos | J12: Código deDepósito | K12: Código de Sector
C13: =+Migrar!E3 -> 3/_A/1/001 | D13: =+Migrar!F3 -> Nave 3 - Pasillo A - N 1 - Pos: 001 | E13: 1 | F13: =+C13 -> 3/_A/1/001 | G13: =+Migrar!I3 -> 1000 | H13: 3 | I13: =+Migrar!K3 -> 100 | J13: =+Migrar!L3 -> 0 | K13: =+Migrar!M3 -> LOG
C14: =+Migrar!E4 -> 3/_A/1/002 | D14: =+Migrar!F4 -> Nave 3 - Pasillo A - N 1 - Pos: 002 | E14: 1 | F14: =+C14 -> 3/_A/1/002 | G14: =+Migrar!I4 -> 1000 | H14: =+Migrar!J4 -> 3 | I14: =+Migrar!K4 -> 100 | J14: =+Migrar!L4 -> 0 | K14: =+Migrar!M4 -> LOG
C15: =+Migrar!E5 -> 3/_A/1/003 | D15: =+Migrar!F5 -> Nave 3 - Pasillo A - N 1 - Pos: 003 | E15: 1 | F15: =+C15 -> 3/_A/1/003 | G15: =+Migrar!I5 -> 1000 | H15: =+Migrar!J5 -> 3 | I15: =+Migrar!K5 -> 100 | J15: =+Migrar!L5 -> 0 | K15: =+Migrar!M5 -> LOG
C16: =+Migrar!E6 -> 3/_A/1/004 | D16: =+Migrar!F6 -> Nave 3 - Pasillo A - N 1 - Pos: 004 | E16: 1 | F16: =+C16 -> 3/_A/1/004 | G16: =+Migrar!I6 -> 1000 | H16: =+Migrar!J6 -> 3 | I16: =+Migrar!K6 -> 100 | J16: =+Migrar!L6 -> 0 | K16: =+Migrar!M6 -> LOG
C17: =+Migrar!E7 -> 3/_A/1/005 | D17: =+Migrar!F7 -> Nave 3 - Pasillo A - N 1 - Pos: 005 | E17: 1 | F17: =+C17 -> 3/_A/1/005 | G17: =+Migrar!I7 -> 1000 | H17: =+Migrar!J7 -> 3 | I17: =+Migrar!K7 -> 100 | J17: =+Migrar!L7 -> 0 | K17: =+Migrar!M7 -> LOG
C18: =+Migrar!E8 -> 3/_A/1/006 | D18: =+Migrar!F8 -> Nave 3 - Pasillo A - N 1 - Pos: 006 | E18: 1 | F18: =+C18 -> 3/_A/1/006 | G18: =+Migrar!I8 -> 1000 | H18: =+Migrar!J8 -> 3 | I18: =+Migrar!K8 -> 100 | J18: =+Migrar!L8 -> 0 | K18: =+Migrar!M8 -> LOG
C19: =+Migrar!E9 -> 3/_A/1/007 | D19: =+Migrar!F9 -> Nave 3 - Pasillo A - N 1 - Pos: 007 | E19: 1 | F19: =+C19 -> 3/_A/1/007 | G19: =+Migrar!I9 -> 1000 | H19: =+Migrar!J9 -> 3 | I19: =+Migrar!K9 -> 100 | J19: =+Migrar!L9 -> 0 | K19: =+Migrar!M9 -> LOG
C20: =+Migrar!E10 -> 3/_A/1/008 | D20: =+Migrar!F10 -> Nave 3 - Pasillo A - N 1 - Pos: 008 | E20: 1 | F20: =+C20 -> 3/_A/1/008 | G20: =+Migrar!I10 -> 1000 | H20: =+Migrar!J10 -> 3 | I20: =+Migrar!K10 -> 100 | J20: =+Migrar!L10 -> 0 | K20: =+Migrar!M10 -> LOG
C21: =+Migrar!E11 -> 3/_A/1/009 | D21: =+Migrar!F11 -> Nave 3 - Pasillo A - N 1 - Pos: 009 | E21: 1 | F21: =+C21 -> 3/_A/1/009 | G21: =+Migrar!I11 -> 1000 | H21: =+Migrar!J11 -> 3 | I21: =+Migrar!K11 -> 100 | J21: =+Migrar!L11 -> 0 | K21: =+Migrar!M11 -> LOG
C22: =+Migrar!E12 -> 3/_A/1/010 | D22: =+Migrar!F12 -> Nave 3 - Pasillo A - N 1 - Pos: 010 | E22: 1 | F22: =+C22 -> 3/_A/1/010 | G22: =+Migrar!I12 -> 1000 | H22: =+Migrar!J12 -> 3 | I22: =+Migrar!K12 -> 100 | J22: =+Migrar!L12 -> 0 | K22: =+Migrar!M12 -> LOG
C23: =+Migrar!E13 -> 3/_A/1/011 | D23: =+Migrar!F13 -> Nave 3 - Pasillo A - N 1 - Pos: 011 | E23: 1 | F23: =+C23 -> 3/_A/1/011 | G23: =+Migrar!I13 -> 1000 | H23: =+Migrar!J13 -> 3 | I23: =+Migrar!K13 -> 100 | J23: =+Migrar!L13 -> 0 | K23: =+Migrar!M13 -> LOG
C24: =+Migrar!E14 -> 3/_A/1/012 | D24: =+Migrar!F14 -> Nave 3 - Pasillo A - N 1 - Pos: 012 | E24: 1 | F24: =+C24 -> 3/_A/1/012 | G24: =+Migrar!I14 -> 1000 | H24: =+Migrar!J14 -> 3 | I24: =+Migrar!K14 -> 100 | J24: =+Migrar!L14 -> 0 | K24: =+Migrar!M14 -> LOG
C25: =+Migrar!E15 -> 3/_A/1/013 | D25: =+Migrar!F15 -> Nave 3 - Pasillo A - N 1 - Pos: 013 | E25: 1 | F25: =+C25 -> 3/_A/1/013 | G25: =+Migrar!I15 -> 1000 | H25: =+Migrar!J15 -> 3 | I25: =+Migrar!K15 -> 100 | J25: =+Migrar!L15 -> 0 | K25: =+Migrar!M15 -> LOG
... C1357: =+Migrar!E1347 -> 3/_K/5/011 | D1357: =+Migrar!F1347 -> Nave 3 - Pasillo k - N 5 - Pos: 011 | E1357: 1 | F1357: =+C1357 -> 3/_K/5/011 | G1357: =+Migrar!I1347 -> 1000 | H1357: =+Migrar!J1347 -> 3 | I1357: =+Migrar!K1347 -> 100 | J1357: =+Migrar!L1347 -> 1 | K1357: =+Migrar!M1347 -> LOG

Sheet Subir a Global
L1: Aclaración: Para subir a Global, se debe loguear con usuario SOPORTE y subir desde Utilidades >> Incorporación de Datos de Planillas
B4: 1 | C4: 2 | D4: 3 | E4: 4 | F4: 5 | G4: 6 | H4: 7 | I4: 8 | J4: 9
A7: Copiar desde acá | B7: T8Ubi
B8: C8Ubi_CodUbi | C8: C8Ubi_Des | D8: C8Ubi_Hab | E8: C8Ubi_CodBar | F8: C8Ubi_MaxPesBru | G8: C8Ubi_MaxVol | H8: C8Ubi_MaxBul | I8: C8Ubi_idDep | J8: C8Ubi_idSec
B9: =+Ubicaciones!C13 -> 3/_A/1/001 | C9: =+Ubicaciones!D13 -> Nave 3 - Pasillo A - N 1 - Pos: 001 | D9: =+Ubicaciones!E13 -> 1 | E9: =+Ubicaciones!F13 -> 3/_A/1/001 | F9: =+Ubicaciones!G13 -> 1000 | G9: 3 | H9: =+Ubicaciones!I13 -> 100 | I9: =+Ubicaciones!J13 -> 0 | J9: =+Ubicaciones!K13 -> LOG
B10: =+Ubicaciones!C14 -> 3/_A/1/002 | C10: =+Ubicaciones!D14 -> Nave 3 - Pasillo A - N 1 - Pos: 002 | D10: =+Ubicaciones!E14 -> 1 | E10: =+Ubicaciones!F14 -> 3/_A/1/002 | F10: =+Ubicaciones!G14 -> 1000 | G10: =+Ubicaciones!H14 -> 3 | H10: =+Ubicaciones!I14 -> 100 | I10: =+Ubicaciones!J14 -> 0 | J10: =+Ubicaciones!K14 -> LOG
B11: =+Ubicaciones!C15 -> 3/_A/1/003 | C11: =+Ubicaciones!D15 -> Nave 3 - Pasillo A - N 1 - Pos: 003 | D11: =+Ubicaciones!E15 -> 1 | E11: =+Ubicaciones!F15 -> 3/_A/1/003 | F11: =+Ubicaciones!G15 -> 1000 | G11: =+Ubicaciones!H15 -> 3 | H11: =+Ubicaciones!I15 -> 100 | I11: =+Ubicaciones!J15 -> 0 | J11: =+Ubicaciones!K15 -> LOG
B12: =+Ubicaciones!C16 -> 3/_A/1/004 | C12: =+Ubicaciones!D16 -> Nave 3 - Pasillo A - N 1 - Pos: 004 | D12: =+Ubicaciones!E16 -> 1 | E12: =+Ubicaciones!F16 -> 3/_A/1/004 | F12: =+Ubicaciones!G16 -> 1000 | G12: =+Ubicaciones!H16 -> 3 | H12: =+Ubicaciones!I16 -> 100 | I12: =+Ubicaciones!J16 -> 0 | J12: =+Ubicaciones!K16 -> LOG
B13: =+Ubicaciones!C17 -> 3/_A/1/005 | C13: =+Ubicaciones!D17 -> Nave 3 - Pasillo A - N 1 - Pos: 005 | D13: =+Ubicaciones!E17 -> 1 | E13: =+Ubicaciones!F17 -> 3/_A/1/005 | F13: =+Ubicaciones!G17 -> 1000 | G13: =+Ubicaciones!H17 -> 3 | H13: =+Ubicaciones!I17 -> 100 | I13: =+Ubicaciones!J17 -> 0 | J13: =+Ubicaciones!K17 -> LOG
B14: =+Ubicaciones!C18 -> 3/_A/1/006 | C14: =+Ubicaciones!D18 -> Nave 3 - Pasillo A - N 1 - Pos: 006 | D14: =+Ubicaciones!E18 -> 1 | E14: =+Ubicaciones!F18 -> 3/_A/1/006 | F14: =+Ubicaciones!G18 -> 1000 | G14: =+Ubicaciones!H18 -> 3 | H14: =+Ubicaciones!I18 -> 100 | I14: =+Ubicaciones!J18 -> 0 | J14: =+Ubicaciones!K18 -> LOG
B15: =+Ubicaciones!C19 -> 3/_A/1/007 | C15: =+Ubicaciones!D19 -> Nave 3 - Pasillo A - N 1 - Pos: 007 | D15: =+Ubicaciones!E19 -> 1 | E15: =+Ubicaciones!F19 -> 3/_A/1/007 | F15: =+Ubicaciones!G19 -> 1000 | G15: =+Ubicaciones!H19 -> 3 | H15: =+Ubicaciones!I19 -> 100 | I15: =+Ubicaciones!J19 -> 0 | J15: =+Ubicaciones!K19 -> LOG
B16: =+Ubicaciones!C20 -> 3/_A/1/008 | C16: =+Ubicaciones!D20 -> Nave 3 - Pasillo A - N 1 - Pos: 008 | D16: =+Ubicaciones!E20 -> 1 | E16: =+Ubicaciones!F20 -> 3/_A/1/008 | F16: =+Ubicaciones!G20 -> 1000 | G16: =+Ubicaciones!H20 -> 3 | H16: =+Ubicaciones!I20 -> 100 | I16: =+Ubicaciones!J20 -> 0 | J16: =+Ubicaciones!K20 -> LOG
B17: =+Ubicaciones!C21 -> 3/_A/1/009 | C17: =+Ubicaciones!D21 -> Nave 3 - Pasillo A - N 1 - Pos: 009 | D17: =+Ubicaciones!E21 -> 1 | E17: =+Ubicaciones!F21 -> 3/_A/1/009 | F17: =+Ubicaciones!G21 -> 1000 | G17: =+Ubicaciones!H21 -> 3 | H17: =+Ubicaciones!I21 -> 100 | I17: =+Ubicaciones!J21 -> 0 | J17: =+Ubicaciones!K21 -> LOG
B18: =+Ubicaciones!C22 -> 3/_A/1/010 | C18: =+Ubicaciones!D22 -> Nave 3 - Pasillo A - N 1 - Pos: 010 | D18: =+Ubicaciones!E22 -> 1 | E18: =+Ubicaciones!F22 -> 3/_A/1/010 | F18: =+Ubicaciones!G22 -> 1000 | G18: =+Ubicaciones!H22 -> 3 | H18: =+Ubicaciones!I22 -> 100 | I18: =+Ubicaciones!J22 -> 0 | J18: =+Ubicaciones!K22 -> LOG
B19: =+Ubicaciones!C23 -> 3/_A/1/011 | C19: =+Ubicaciones!D23 -> Nave 3 - Pasillo A - N 1 - Pos: 011 | D19: =+Ubicaciones!E23 -> 1 | E19: =+Ubicaciones!F23 -> 3/_A/1/011 | F19: =+Ubicaciones!G23 -> 1000 | G19: =+Ubicaciones!H23 -> 3 | H19: =+Ubicaciones!I23 -> 100 | I19: =+Ubicaciones!J23 -> 0 | J19: =+Ubicaciones!K23 -> LOG
B20: =+Ubicaciones!C24 -> 3/_A/1/012 | C20: =+Ubicaciones!D24 -> Nave 3 - Pasillo A - N 1 - Pos: 012 | D20: =+Ubicaciones!E24 -> 1 | E20: =+Ubicaciones!F24 -> 3/_A/1/012 | F20: =+Ubicaciones!G24 -> 1000 | G20: =+Ubicaciones!H24 -> 3 | H20: =+Ubicaciones!I24 -> 100 | I20: =+Ubicaciones!J24 -> 0 | J20: =+Ubicaciones!K24 -> LOG
B21: =+Ubicaciones!C25 -> 3/_A/1/013 | C21: =+Ubicaciones!D25 -> Nave 3 - Pasillo A - N 1 - Pos: 013 | D21: =+Ubicaciones!E25 -> 1 | E21: =+Ubicaciones!F25 -> 3/_A/1/013 | F21: =+Ubicaciones!G25 -> 1000 | G21: =+Ubicaciones!H25 -> 3 | H21: =+Ubicaciones!I25 -> 100 | I21: =+Ubicaciones!J25 -> 0 | J21: =+Ubicaciones!K25 -> LOG
... B1353: =+Ubicaciones!C1357 -> 3/_K/5/011 | C1353: =+Ubicaciones!D1357 -> Nave 3 - Pasillo k - N 5 - Pos: 011 | D1353: =+Ubicaciones!E1357 -> 1 | E1353: =+Ubicaciones!F1357 -> 3/_K/5/011 | F1353: =+Ubicaciones!G1357 -> 1000 | G1353: =+Ubicaciones!H1357 -> 3 | H1353: =+Ubicaciones!I1357 -> 100 | I1353: =+Ubicaciones!J1357 -> 1 | J1353: =+Ubicaciones!K1357 -> LOG

Sheet Migrar
A2: Nave | B2: Pasillo | C2: Nivel | D2: Posición | E2: Código | F2: Nombre | G2: Habilitado | H2: Código de Barras | I2: Peso Bruto Máximo | J2: Volúmen Máximo | K2: Bultos Máximos | L2: Depósito | M2: Sector
A3: 3 | B3: _A | C3: 1 | D3: 001 | E3: =CONCATENATE(A3,"/",'[1]Planilla Migración'!B2,"/",C3,"/",D3) -> 3/_A/1/001 | F3: Nave 3 - Pasillo A - N 1 - Pos: 001 | G3: 0 | I3: 1000 | J3: 3 | K3: 100 | L3: 0 | M3: LOG
A4: 3 | B4: _A | C4: 1 | D4: 002 | E4: =CONCATENATE(A4,"/",'[1]Planilla Migración'!B3,"/",C4,"/",D4) -> 3/_A/1/002 | F4: Nave 3 - Pasillo A - N 1 - Pos: 002 | G4: 0 | I4: 1000 | J4: 3 | K4: 100 | L4: 0 | M4: LOG
A5: 3 | B5: _A | C5: 1 | D5: 003 | E5: =CONCATENATE(A5,"/",'[1]Planilla Migración'!B4,"/",C5,"/",D5) -> 3/_A/1/003 | F5: Nave 3 - Pasillo A - N 1 - Pos: 003 | G5: 0 | I5: 1000 | J5: 3 | K5: 100 | L5: 0 | M5: LOG
A6: 3 | B6: _A | C6: 1 | D6: 004 | E6: =CONCATENATE(A6,"/",'[1]Planilla Migración'!B5,"/",C6,"/",D6) -> 3/_A/1/004 | F6: Nave 3 - Pasillo A - N 1 - Pos: 004 | G6: 0 | I6: 1000 | J6: 3 | K6: 100 | L6: 0 | M6: LOG
A7: 3 | B7: _A | C7: 1 | D7: 005 | E7: =CONCATENATE(A7,"/",'[1]Planilla Migración'!B6,"/",C7,"/",D7) -> 3/_A/1/005 | F7: Nave 3 - Pasillo A - N 1 - Pos: 005 | G7: 0 | I7: 1000 | J7: 3 | K7: 100 | L7: 0 | M7: LOG
A8: 3 | B8: _A | C8: 1 | D8: 006 | E8: =CONCATENATE(A8,"/",'[1]Planilla Migración'!B7,"/",C8,"/",D8) -> 3/_A/1/006 | F8: Nave 3 - Pasillo A - N 1 - Pos: 006 | G8: 0 | I8: 1000 | J8: 3 | K8: 100 | L8: 0 | M8: LOG
A9: 3 | B9: _A | C9: 1 | D9: 007 | E9: =CONCATENATE(A9,"/",'[1]Planilla Migración'!B8,"/",C9,"/",D9) -> 3/_A/1/007 | F9: Nave 3 - Pasillo A - N 1 - Pos: 007 | G9: 0 | I9: 1000 | J9: 3 | K9: 100 | L9: 0 | M9: LOG
A10: 3 | B10: _A | C10: 1 | D10: 008 | E10: =CONCATENATE(A10,"/",'[1]Planilla Migración'!B9,"/",C10,"/",D10) -> 3/_A/1/008 | F10: Nave 3 - Pasillo A - N 1 - Pos: 008 | G10: 0 | I10: 1000 | J10: 3 | K10: 100 | L10: 0 | M10: LOG
A11: 3 | B11: _A | C11: 1 | D11: 009 | E11: =CONCATENATE(A11,"/",'[1]Planilla Migración'!B10,"/",C11,"/",D11) -> 3/_A/1/009 | F11: Nave 3 - Pasillo A - N 1 - Pos: 009 | G11: 0 | I11: 1000 | J11: 3 | K11: 100 | L11: 0 | M11: LOG
A12: 3 | B12: _A | C12: 1 | D12: 010 | E12: =CONCATENATE(A12,"/",'[1]Planilla Migración'!B11,"/",C12,"/",D12) -> 3/_A/1/010 | F12: Nave 3 - Pasillo A - N 1 - Pos: 010 | G12: 0 | I12: 1000 | J12: 3 | K12: 100 | L12: 0 | M12: LOG
A13: 3 | B13: _A | C13: 1 | D13: 011 | E13: =CONCATENATE(A13,"/",'[1]Planilla Migración'!B12,"/",C13,"/",D13) -> 3/_A/1/011 | F13: Nave 3 - Pasillo A - N 1 - Pos: 011 | G13: 0 | I13: 1000 | J13: 3 | K13: 100 | L13: 0 | M13: LOG
A14: 3 | B14: _A | C14: 1 | D14: 012 | E14: =CONCATENATE(A14,"/",'[1]Planilla Migración'!B13,"/",C14,"/",D14) -> 3/_A/1/012 | F14: Nave 3 - Pasillo A - N 1 - Pos: 012 | G14: 0 | I14: 1000 | J14: 3 | K14: 100 | L14: 0 | M14: LOG
... A134: 3 | B134: _B | C134: 1 | D134: 027 | E134: =CONCATENATE(A134,"/",'[1]Planilla Migración'!B133,"/",C134,"/",D134) -> 3/_B/1/027 | F134: Nave 3 - Pasillo B - N 1 - Pos: 027 | G134: 0 | I134: 1000 | J134: 3 | K134: 100 | L134: 0 | M134: LOG
A135: 3 | B135: _B | C135: 2 | D135: 001 | E135: =CONCATENATE(A135,"/",'[1]Planilla Migración'!B134,"/",C135,"/",D135) -> 3/_B/2/001 | F135: Nave 3 - Pasillo B - N 2 - Pos: 001 | G135: 0 | I135: 1000 | J135: 3 | K135: 100 | L135: 0 | M135: LOG
A136: 3 | B136: _B | C136: 2 | D136: 002 | E136: =CONCATENATE(A136,"/",'[1]Planilla Migración'!B135,"/",C136,"/",D136) -> 3/_B/2/002 | F136: Nave 3 - Pasillo B - N 2 - Pos: 002 | G136: 0 | I136: 1000 | J136: 3 | K136: 100 | L136: 0 | M136: LOG
A137: 3 | B137: _B | C137: 2 | D137: 003 | E137: =CONCATENATE(A137,"/",'[1]Planilla Migración'!B136,"/",C137,"/",D137) -> 3/_B/2/003 | F137: Nave 3 - Pasillo B - N 2 - Pos: 003 | G137: 0 | I137: 1000 | J137: 3 | K137: 100 | L137: 0 | M137: LOG
A138: 3 | B138: _B | C138: 2 | D138: 004 | E138: =CONCATENATE(A138,"/",'[1]Planilla Migración'!B137,"/",C138,"/",D138) -> 3/_B/2/004 | F138: Nave 3 - Pasillo B - N 2 - Pos: 004 | G138: 0 | I138: 1000 | J138: 3 | K138: 100 | L138: 0 | M138: LOG
A139: 3 | B139: _B | C139: 2 | D139: 005 | E139: =CONCATENATE(A139,"/",'[1]Planilla Migración'!B138,"/",C139,"/",D139) -> 3/_B/2/005 | F139: Nave 3 - Pasillo B - N 2 - Pos: 005 | G139: 0 | I139: 1000 | J139: 3 | K139: 100 | L139: 0 | M139: LOG
A140: 3 | B140: _B | C140: 2 | D140: 006 | E140: =CONCATENATE(A140,"/",'[1]Planilla Migración'!B139,"/",C140,"/",D140) -> 3/_B/2/006 | F140: Nave 3 - Pasillo B - N 2 - Pos: 006 | G140: 0 | I140: 1000 | J140: 3 | K140: 100 | L140: 0 | M140: LOG
A141: 3 | B141: _B | C141: 2 | D141: 007 | E141: =CONCATENATE(A141,"/",'[1]Planilla Migración'!B140,"/",C141,"/",D141) -> 3/_B/2/007 | F141: Nave 3 - Pasillo B - N 2 - Pos: 007 | G141: 0 | I141: 1000 | J141: 3 | K141: 100 | L141: 0 | M141: LOG
A142: 3 | B142: _B | C142: 2 | D142: 008 | E142: =CONCATENATE(A142,"/",'[1]Planilla Migración'!B141,"/",C142,"/",D142) -> 3/_B/2/008 | F142: Nave 3 - Pasillo B - N 2 - Pos: 008 | G142: 0 | I142: 1000 | J142: 3 | K142: 100 | L142: 0 | M142: LOG
A143: 3 | B143: _B | C143: 2 | D143: 009 | E143: =CONCATENATE(A143,"/",'[1]Planilla Migración'!B142,"/",C143,"/",D143) -> 3/_B/2/009 | F143: Nave 3 - Pasillo B - N 2 - Pos: 009 | G143: 0 | I143: 1000 | J143: 3 | K143: 100 | L143: 0 | M143: LOG
A144: 3 | B144: _B | C144: 2 | D144: 010 | E144: =CONCATENATE(A144,"/",'[1]Planilla Migración'!B143,"/",C144,"/",D144) -> 3/_B/2/010 | F144: Nave 3 - Pasillo B - N 2 - Pos: 010 | G144: 0 | I144: 1000 | J144: 3 | K144: 100 | L144: 0 | M144: LOG
A145: 3 | B145: _B | C145: 2 | D145: 011 | E145: =CONCATENATE(A145,"/",'[1]Planilla Migración'!B144,"/",C145,"/",D145) -> 3/_B/2/011 | F145: Nave 3 - Pasillo B - N 2 - Pos: 011 | G145: 0 | I145: 1000 | J145: 3 | K145: 100 | L145: 0 | M145: LOG
A146: 3 | B146: _B | C146: 2 | D146: 012 | E146: =CONCATENATE(A146,"/",'[1]Planilla Migración'!B145,"/",C146,"/",D146) -> 3/_B/2/012 | F146: Nave 3 - Pasillo B - N 2 - Pos: 012 | G146: 0 | I146: 1000 | J146: 3 | K146: 100 | L146: 0 | M146: LOG
... A161: 3 | B161: _B | C161: 2 | D161: 027 | E161: =CONCATENATE(A161,"/",'[1]Planilla Migración'!B160,"/",C161,"/",D161) -> 3/_B/2/027 | F161: Nave 3 - Pasillo B - N 2 - Pos: 027 | G161: 0 | I161: 1000 | J161: 3 | K161: 100 | L161: 0 | M161: LOG
A162: 3 | B162: _B | C162: 3 | D162: 001 | E162: =CONCATENATE(A162,"/",'[1]Planilla Migración'!B161,"/",C162,"/",D162) -> 3/_B/3/001 | F162: Nave 3 - Pasillo B - N 3 - Pos: 001 | G162: 0 | I162: 1000 | J162: 3 | K162: 100 | L162: 0 | M162: LOG
A163: 3 | B163: _B | C163: 3 | D163: 002 | E163: =CONCATENATE(A163,"/",'[1]Planilla Migración'!B162,"/",C163,"/",D163) -> 3/_B/3/002 | F163: Nave 3 - Pasillo B - N 3 - Pos: 002 | G163: 0 | I163: 1000 | J163: 3 | K163: 100 | L163: 0 | M163: LOG
A164: 3 | B164: _B | C164: 3 | D164: 003 | E164: =CONCATENATE(A164,"/",'[1]Planilla Migración'!B163,"/",C164,"/",D164) -> 3/_B/3/003 | F164: Nave 3 - Pasillo B - N 3 - Pos: 003 | G164: 0 | I164: 1000 | J164: 3 | K164: 100 | L164: 0 | M164: LOG
A165: 3 | B165: _B | C165: 3 | D165: 004 | E165: =CONCATENATE(A165,"/",'[1]Planilla Migración'!B164,"/",C165,"/",D165) -> 3/_B/3/004 | F165: Nave 3 - Pasillo B - N 3 - Pos: 004 | G165: 0 | I165: 1000 | J165: 3 | K165: 100 | L165: 0 | M165: LOG
A166: 3 | B166: _B | C166: 3 | D166: 005 | E166: =CONCATENATE(A166,"/",'[1]Planilla Migración'!B165,"/",C166,"/",D166) -> 3/_B/3/005 | F166: Nave 3 - Pasillo B - N 3 - Pos: 005 | G166: 0 | I166: 1000 | J166: 3 | K166: 100 | L166: 0 | M166: LOG
A167: 3 | B167: _B | C167: 3 | D167: 006 | E167: =CONCATENATE(A167,"/",'[1]Planilla Migración'!B166,"/",C167,"/",D167) -> 3/_B/3/006 | F167: Nave 3 - Pasillo B - N 3 - Pos: 006 | G167: 0 | I167: 1000 | J167: 3 | K167: 100 | L167: 0 | M167: LOG
A168: 3 | B168: _B | C168: 3 | D168: 007 | E168: =CONCATENATE(A168,"/",'[1]Planilla Migración'!B167,"/",C168,"/",D168) -> 3/_B/3/007 | F168: Nave 3 - Pasillo B - N 3 - Pos: 007 | G168: 0 | I168: 1000 | J168: 3 | K168: 100 | L168: 0 | M168: LOG
A169: 3 | B169: _B | C169: 3 | D169: 008 | E169: =CONCATENATE(A169,"/",'[1]Planilla Migración'!B168,"/",C169,"/",D169) -> 3/_B/3/008 | F169: Nave 3 - Pasillo B - N 3 - Pos: 008 | G169: 0 | I169: 1000 | J169: 3 | K169: 100 | L169: 0 | M169: LOG
A170: 3 | B170: _B | C170: 3 | D170: 009 | E170: =CONCATENATE(A170,"/",'[1]Planilla Migración'!B169,"/",C170,"/",D170) -> 3/_B/3/009 | F170: Nave 3 - Pasillo B - N 3 - Pos: 009 | G170: 0 | I170: 1000 | J170: 3 | K170: 100 | L170: 0 | M170: LOG
A171: 3 | B171: _B | C171: 3 | D171: 010 | E171: =CONCATENATE(A171,"/",'[1]Planilla Migración'!B170,"/",C171,"/",D171) -> 3/_B/3/010 | F171: Nave 3 - Pasillo B - N 3 - Pos: 010 | G171: 0 | I171: 1000 | J171: 3 | K171: 100 | L171: 0 | M171: LOG
A172: 3 | B172: _B | C172: 3 | D172: 011 | E172: =CONCATENATE(A172,"/",'[1]Planilla Migración'!B171,"/",C172,"/",D172) -> 3/_B/3/011 | F172: Nave 3 - Pasillo B - N 3 - Pos: 011 | G172: 0 | I172: 1000 | J172: 3 | K172: 100 | L172: 0 | M172: LOG
A173: 3 | B173: _B | C173: 3 | D173: 012 | E173: =CONCATENATE(A173,"/",'[1]Planilla Migración'!B172,"/",C173,"/",D173) -> 3/_B/3/012 | F173: Nave 3 - Pasillo B - N 3 - Pos: 012 | G173: 0 | I173: 1000 | J173: 3 | K173: 100 | L173: 0 | M173: LOG
... A269: 3 | B269: _C | C269: 1 | D269: 027 | E269: =CONCATENATE(A269,"/",'[1]Planilla Migración'!B268,"/",C269,"/",D269) -> 3/_C/1/027 | F269: Nave 3 - Pasillo C - N 1 - Pos: 027 | G269: 0 | I269: 1000 | J269: 3 | K269: 100 | L269: 0 | M269: LOG
...
